Workbook

Sheet Summary Sheet
B1: Asking Rent | F1: Effective Rent | J1: Employment | P1: Supply | U1: Units Per Person | X1: Income | AB1: Population | AH1: Sale Price | AQ1: Check: | AU1: PASTE HERE: | AY1: 2025 Analysis
A2: Weighting | H2: 0.2 | K2: 0.1 | N2: 0.1 | V2: 0.2 | AC2: 0.1 | AF2: 0.1 | AN2: 0.2 | AQ2: =SUM(B2:AP2) -> 1
A3: Market | B3: Forward 1 | C3: Forward 3 | D3: Forward 5 | E3: Forward 10 | F3: Forward 1 | G3: Forward 3 | H3: Forward 5 | I3: Forward 10 | J3: 10 Yr. Hist | K3: 5 Yr. Hist | L3: Forward 1 | M3: Forward 3 | N3: Forward 5 | O3: Forward 10 | P3: Historical 5 | Q3: Forward 1 | R3: Forward 3 | S3: Forward 5 | T3: Forward 10 | U3: Historical 10 | V3: Forward 5 | W3: Forward 10 | X3: Forward 1 | Y3: Forward 3 | Z3: Forward 5 | AA3: Forward 10 | AB3: 10 Yr. Hist | AC3: 5 Yr. Hist | AD3: Forward 1 | AE3: Forward 3 | AF3: Forward 5 | AG3: Forward 10 | AH3: Historical 1 | AI3: Historical 3 | AJ3: Historical 5 | AK3: Historical 10 | AL3: Forward 1 | AM3: Forward 3 | AN3: Forward 5 | AO3: Forward 10 | AP3: Simple Average | AQ3: Weighted Average | AT3: Market | AU3: Weighted Avg. | AV3: Rank | AY3: Market | AZ3: Weighted Avg. | BA3: Rank
A4: Akron - OH | B4: ='Asking Rent'!I307 -> 61 | C4: ='Asking Rent'!M307 -> 62 | D4: ='Asking Rent'!Q307 -> 71 | E4: ='Asking Rent'!U307 -> 113 | F4: ='Effective Rent-Forward'!I307 -> 33 | G4: ='Effective Rent-Forward'!N307 -> 79 | H4: ='Effective Rent-Forward'!R307 -> 69 | I4: ='Effective Rent-Forward'!V307 -> 114 | J4: ='Historical Employment'!H458 -> 140 | K4: ='Historical Employment'!D458 -> 134 | L4: ='Forward Employment'!I308 -> 140 | M4: ='Forward Employment'!M308 -> 140 | N4: ='Forward Employment'!Q308 -> 144 | O4: ='Forward Employment'!U308 -> 143 | P4: ='Supply Historical'!C308 -> 25 | Q4: ='Supply Forward'!I307 -> 6 | R4: ='Supply Forward'!M307 -> 9 | S4: ='Supply Forward'!Q307 -> 10 | T4: ='Supply Forward'!U307 -> 18 | U4: ='UPP Historical'!C619 -> 33 | V4: ='Forward UPP'!C613 -> 50 | W4: ='Forward UPP'!F613 | X4: ='Income Growth'!I307 -> 123 | Y4: ='Income Growth'!M307 -> 87 | Z4: ='Income Growth'!Q307 -> 84 | AA4: ='Income Growth'!U307 -> 91 | AB4: ='Historical Population Growth'!I458 -> 129 | AC4: ='Historical Population Growth'!D458 -> 121 | AD4: ='Population Growth Forward'!I307 -> 128 | AE4: ='Population Growth Forward'!M307 -> 134 | AF4: ='Population Growth Forward'!Q307 -> 137 | AG4: ='Population Growth Forward'!U307 -> 142 | AH4: ='Historical Sale Price'!I763 -> 52 | AI4: ='Historical Sale Price'!M763 -> 25 | AJ4: ='Historical Sale Price'!Q763 -> 24 | AK4: ='Historical Sale Price'!U763 -> 99 | AL4: ='Forward Sale Price'!I307 -> 74 | AM4: ='Forward Sale Price'!M307 -> 106 | AN4: ='Forward Sale Price'!Q307 -> 116 | AO4: ='Forward Sale Price'!U307 -> 132 | AP4: =AVERAGE(B4:AO4) -> 87.128205 | AQ4: =SUMPRODUCT(B$2:AO$2,B4:AO4) -> 100.6 | AS4: Akron - OH | AT4: Inland Empire - CA | AU4: 20.2 | AV4: =RANK(AU4,AU$4:AU$153,-1) -> 1 | AY4: Austin - TX | AZ4: 17.8 | BA4: 1
A5: Albany - NY | B5: ='Asking Rent'!I308 -> 31 | C5: ='Asking Rent'!M308 -> 20 | D5: ='Asking Rent'!Q308 -> 23 | E5: ='Asking Rent'!U308 -> 37 | F5: ='Effective Rent-Forward'!I308 -> 23 | G5: ='Effective Rent-Forward'!N308 -> 22 | H5: ='Effective Rent-Forward'!R308 -> 24 | I5: ='Effective Rent-Forward'!V308 -> 34 | J5: ='Historical Employment'!H459 -> 125 | K5: ='Historical Employment'!D459 -> 93 | L5: ='Forward Employment'!I309 -> 113 | M5: ='Forward Employment'!M309 -> 126 | N5: ='Forward Employment'!Q309 -> 127 | O5: ='Forward Employment'!U309 -> 123 | P5: ='Supply Historical'!C309 -> 43 | Q5: ='Supply Forward'!I308 -> 83 | R5: ='Supply Forward'!M308 -> 55 | S5: ='Supply Forward'!Q308 -> 53 | T5: ='Supply Forward'!U308 -> 48 | U5: ='UPP Historical'!C620 -> 83 | V5: ='Forward UPP'!C614 -> 85 | W5: ='Forward UPP'!F614 | X5: ='Income Growth'!I308 -> 40 | Y5: ='Income Growth'!M308 -> 72 | Z5: ='Income Growth'!Q308 -> 75 | AA5: ='Income Growth'!U308 -> 84 | AB5: ='Historical Population Growth'!I459 -> 108 | AC5: ='Historical Population Growth'!D459 -> 112 | AD5: ='Population Growth Forward'!I308 -> 118 | AE5: ='Population Growth Forward'!M308 -> 117 | AF5: ='Population Growth Forward'!Q308 -> 122 | AG5: ='Population Growth Forward'!U308 -> 119 | AH5: ='Historical Sale Price'!I764 -> 41 | AI5: ='Historical Sale Price'!M764 -> 49 | AJ5: ='Historical Sale Price'!Q764 -> 119 | AK5: ='Historical Sale Price'!U764 -> 124 | AL5: ='Forward Sale Price'!I308 -> 52 | AM5: ='Forward Sale Price'!M308 -> 53 | AN5: ='Forward Sale Price'!Q308 -> 55 | AO5: ='Forward Sale Price'!U308 -> 59 | AP5: =AVERAGE(B5:AO5) -> 74.102564 | AQ5: =SUMPRODUCT(B$2:AO$2,B5:AO5) -> 78.2 | AS5: Albany - NY | AT5: Las Vegas - NV | AU5: 22.4 | AV5: =RANK(AU5,AU$4:AU$153,-1) -> 2 | AY5: Inland Empire - CA | AZ5: 19.3 | BA5: 2
A6: Albuquerque - NM | B6: ='Asking Rent'!I309 -> 145 | C6: ='Asking Rent'!M309 -> 139 | D6: ='Asking Rent'!Q309 -> 137 | E6: ='Asking Rent'!U309 -> 133 | F6: ='Effective Rent-Forward'!I309 -> 143 | G6: ='Effective Rent-Forward'!N309 -> 140 | H6: ='Effective Rent-Forward'!R309 -> 137 | I6: ='Effective Rent-Forward'!V309 -> 134 | J6: ='Historical Employment'!H460 -> 68 | K6: ='Historical Employment'!D460 -> 40 | L6: ='Forward Employment'!I310 -> 98 | M6: ='Forward Employment'!M310 -> 104 | N6: ='Forward Employment'!Q310 -> 103 | O6: ='Forward Employment'!U310 -> 108 | P6: ='Supply Historical'!C310 -> 41 | Q6: ='Supply Forward'!I309 -> 31 | R6: ='Supply Forward'!M309 -> 49 | S6: ='Supply Forward'!Q309 -> 49 | T6: ='Supply Forward'!U309 -> 49 | U6: ='UPP Historical'!C621 -> 19 | V6: ='Forward UPP'!C615 -> 69 | W6: ='Forward UPP'!F615 | X6: ='Income Growth'!I309 -> 51 | Y6: ='Income Growth'!M309 -> 63 | Z6: ='Income Growth'!Q309 -> 57 | AA6: ='Income Growth'!U309 -> 40 | AB6: ='Historical Population Growth'!I460 -> 107 | AC6: ='Historical Population Growth'!D460 -> 114 | AD6: ='Population Growth Forward'!I309 -> 95 | AE6: ='Population Growth Forward'!M309 -> 98 | AF6: ='Population Growth Forward'!Q309 -> 103 | AG6: ='Population Growth Forward'!U309 -> 108 | AH6: ='Historical Sale Price'!I765 -> 63 | AI6: ='Historical Sale Price'!M765 -> 76 | AJ6: ='Historical Sale Price'!Q765 -> 41 | AK6: ='Historical Sale Price'!U765 -> 49 | AL6: ='Forward Sale Price'!I309 -> 124 | AM6: ='Forward Sale Price'!M309 -> 138 | AN6: ='Forward Sale Price'!Q309 -> 134 | AO6: ='Forward Sale Price'!U309 -> 123 | AP6: =AVERAGE(B6:AO6) -> 90.25641 | AQ6: =SUMPRODUCT(B$2:AO$2,B6:AO6) -> 104 | AS6: Albuquerque - NM | AT6: Stockton - CA | AU6: 28.4 | AV6: =RANK(AU6,AU$4:AU$153,-1) -> 3 | AY6: Raleigh - NC | AZ6: 24.2 | BA6: 3
A7: Anchorage - AK | B7: ='Asking Rent'!I310 -> 73 | C7: ='Asking Rent'!M310 -> 77 | D7: ='Asking Rent'!Q310 -> 89 | E7: ='Asking Rent'!U310 -> 95 | F7: ='Effective Rent-Forward'!I310 -> 33 | G7: ='Effective Rent-Forward'!N310 -> 69 | H7: ='Effective Rent-Forward'!R310 -> 79 | I7: ='Effective Rent-Forward'!V310 -> 87 | J7: ='Historical Employment'!H461 -> 134 | K7: ='Historical Employment'!D461 -> 87 | L7: ='Forward Employment'!I311 -> 133 | M7: ='Forward Employment'!M311 -> 123 | N7: ='Forward Employment'!Q311 -> 118 | O7: ='Forward Employment'!U311 -> 104 | P7: ='Supply Historical'!C311 -> 3 | Q7: ='Supply Forward'!I310 -> 16 | R7: ='Supply Forward'!M310 -> 2 | S7: ='Supply Forward'!Q310 -> 2 | T7: ='Supply Forward'!U310 -> 2 | U7: ='UPP Historical'!C622 -> 4 | V7: ='Forward UPP'!C616 -> 6 | W7: ='Forward UPP'!F616 | X7: ='Income Growth'!I310 -> 139 | Y7: ='Income Growth'!M310 -> 140 | Z7: ='Income Growth'!Q310 -> 146 | AA7: ='Income Growth'!U310 -> 147 | AB7: ='Historical Population Growth'!I461 -> 114 | AC7: ='Historical Population Growth'!D461 -> 99 | AD7: ='Population Growth Forward'!I310 -> 98 | AE7: ='Population Growth Forward'!M310 -> 95 | AF7: ='Population Growth Forward'!Q310 -> 93 | AG7: ='Population Growth Forward'!U310 -> 65 | AH7: ='Historical Sale Price'!I766 -> 66 | AI7: ='Historical Sale Price'!M766 -> 66 | AJ7: ='Historical Sale Price'!Q766 -> 116 | AK7: ='Historical Sale Price'!U766 -> 146 | AL7: ='Forward Sale Price'!I310 -> 27 | AM7: ='Forward Sale Price'!M310 -> 73 | AN7: ='Forward Sale Price'!Q310 -> 82 | AO7: ='Forward Sale Price'!U310 -> 80 | AP7: =AVERAGE(B7:AO7) -> 80.205128 | AQ7: =SUMPRODUCT(B$2:AO$2,B7:AO7) -> 73.1 | AS7: Anchorage - AK | AT7: Fresno - CA | AU7: 32.6 | AV7: =RANK(AU7,AU$4:AU$153,-1) -> 4 | AY7: San Antonio - TX | AZ7: 28 | BA7: 4
A8: Asheville - NC | B8: ='Asking Rent'!I311 -> 116 | C8: ='Asking Rent'!M311 -> 114 | D8: ='Asking Rent'!Q311 -> 113 | E8: ='Asking Rent'!U311 -> 106 | F8: ='Effective Rent-Forward'!I311 -> 88 | G8: ='Effective Rent-Forward'!N311 -> 113 | H8: ='Effective Rent-Forward'!R311 -> 107 | I8: ='Effective Rent-Forward'!V311 -> 105 | J8: ='Historical Employment'!H462 -> 58 | K8: ='Historical Employment'!D462 -> 86 | L8: ='Forward Employment'!I312 -> 70 | M8: ='Forward Employment'!M312 -> 65 | N8: ='Forward Employment'!Q312 -> 60 | O8: ='Forward Employment'!U312 -> 11 | P8: ='Supply Historical'!C312 -> 137 | Q8: ='Supply Forward'!I311 -> 124 | R8: ='Supply Forward'!M311 -> 149 | S8: ='Supply Forward'!Q311 -> 149 | T8: ='Supply Forward'!U311 -> 150 | U8: ='UPP Historical'!C623 -> 147 | V8: ='Forward UPP'!C617 -> 150 | W8: ='Forward UPP'!F617 | X8: ='Income Growth'!I311 -> 121 | Y8: ='Income Growth'!M311 -> 116 | Z8: ='Income Growth'!Q311 -> 117 | AA8: ='Income Growth'!U311 -> 117 | AB8: ='Historical Population Growth'!I462 -> 50 | AC8: ='Historical Population Growth'!D462 -> 51 | AD8: ='Population Growth Forward'!I311 -> 30 | AE8: ='Population Growth Forward'!M311 -> 40 | AF8: ='Population Growth Forward'!Q311 -> 44 | AG8: ='Population Growth Forward'!U311 -> 48 | AH8: ='Historical Sale Price'!I767 -> 70 | AI8: ='Historical Sale Price'!M767 -> 105 | AJ8: ='Historical Sale Price'!Q767 -> 19 | AK8: ='Historical Sale Price'!U767 -> 13 | AL8: ='Forward Sale Price'!I311 -> 122 | AM8: ='Forward Sale Price'!M311 -> 93 | AN8: ='Forward Sale Price'!Q311 -> 83 | AO8: ='Forward Sale Price'!U311 -> 82 | AP8: =AVERAGE(B8:AO8) -> 90.74359 | AQ8: =SUMPRODUCT(B$2:AO$2,B8:AO8) -> 92.1 | AS8: Asheville - NC | AT8: Sacramento - CA | AU8: 32.8 | AV8: =RANK(AU8,AU$4:AU$153,-1) -> 5 | AY8: Reno - NV | AZ8: 33.2 | BA8: 5
A9: Atlanta - GA | B9: ='Asking Rent'!I312 -> 99 | C9: ='Asking Rent'!M312 -> 120 | D9: ='Asking Rent'!Q312 -> 124 | E9: ='Asking Rent'!U312 -> 101 | F9: ='Effective Rent-Forward'!I312 -> 85 | G9: ='Effective Rent-Forward'!N312 -> 114 | H9: ='Effective Rent-Forward'!R312 -> 123 | I9: ='Effective Rent-Forward'!V312 -> 103 | J9: ='Historical Employment'!H463 -> 37 | K9: ='Historical Employment'!D463 -> 52 | L9: ='Forward Employment'!I313 -> 28 | M9: ='Forward Employment'!M313 -> 27 | N9: ='Forward Employment'!Q313 -> 29 | O9: ='Forward Employment'!U313 -> 51 | P9: ='Supply Historical'!C313 -> 104 | Q9: ='Supply Forward'!I312 -> 96 | R9: ='Supply Forward'!M312 -> 108 | S9: ='Supply Forward'!Q312 -> 107 | T9: ='Supply Forward'!U312 -> 108 | U9: ='UPP Historical'!C624 -> 75 | V9: ='Forward UPP'!C618 -> 66 | W9: ='Forward UPP'!F618 | X9: ='Income Growth'!I312 -> 99 | Y9: ='Income Growth'!M312 -> 106 | Z9: ='Income Growth'!Q312 -> 111 | AA9: ='Income Growth'!U312 -> 121 | AB9: ='Historical Population Growth'!I463 -> 33 | AC9: ='Historical Population Growth'!D463 -> 33 | AD9: ='Population Growth Forward'!I312 -> 21 | AE9: ='Population Growth Forward'!M312 -> 20 | AF9: ='Population Growth Forward'!Q312 -> 20 | AG9: ='Population Growth Forward'!U312 -> 19 | AH9: ='Historical Sale Price'!I768 -> 103 | AI9: ='Historical Sale Price'!M768 -> 123 | AJ9: ='Historical Sale Price'!Q768 -> 99 | AK9: ='Historical Sale Price'!U768 -> 47 | AL9: ='Forward Sale Price'!I312 -> 76 | AM9: ='Forward Sale Price'!M312 -> 87 | AN9: ='Forward Sale Price'!Q312 -> 93 | AO9: ='Forward Sale Price'!U312 -> 51 | AP9: =AVERAGE(B9:AO9) -> 77.410256 | AQ9: =SUMPRODUCT(B$2:AO$2,B9:AO9) -> 69.8 | AS9: Atlanta - GA | AT9: Indianapolis - IN | AU9: 35.6 | AV9: =RANK(AU9,AU$4:AU$153,-1) -> 6 | AY9: Stockton - CA | AZ9: 34.8 | BA9: 6
A10: Augusta - GA | B10: ='Asking Rent'!I313 -> 89 | C10: ='Asking Rent'!M313 -> 96 | D10: ='Asking Rent'!Q313 -> 97 | E10: ='Asking Rent'!U313 -> 93 | F10: ='Effective Rent-Forward'!I313 -> 102 | G10: ='Effective Rent-Forward'!N313 -> 102 | H10: ='Effective Rent-Forward'!R313 -> 93 | I10: ='Effective Rent-Forward'!V313 -> 79 | J10: ='Historical Employment'!H464 -> 93 | K10: ='Historical Employment'!D464 -> 145 | L10: ='Forward Employment'!I314 -> 101 | M10: ='Forward Employment'!M314 -> 97 | N10: ='Forward Employment'!Q314 -> 99 | O10: ='Forward Employment'!U314 -> 111 | P10: ='Supply Historical'!C314 -> 121 | Q10: ='Supply Forward'!I313 -> 99 | R10: ='Supply Forward'!M313 -> 84 | S10: ='Supply Forward'!Q313 -> 90 | T10: ='Supply Forward'!U313 -> 89 | U10: ='UPP Historical'!C625 -> 115 | V10: ='Forward UPP'!C619 -> 84 | W10: ='Forward UPP'!F619 | X10: ='Income Growth'!I313 -> 120 | Y10: ='Income Growth'!M313 -> 139 | Z10: ='Income Growth'!Q313 -> 134 | AA10: ='Income Growth'!U313 -> 115 | AB10: ='Historical Population Growth'!I464 -> 56 | AC10: ='Historical Population Growth'!D464 -> 50 | AD10: ='Population Growth Forward'!I313 -> 55 | AE10: ='Population Growth Forward'!M313 -> 61 | AF10: ='Population Growth Forward'!Q313 -> 64 | AG10: ='Population Growth Forward'!U313 -> 75 | AH10: ='Historical Sale Price'!I769 -> 25 | AI10: ='Historical Sale Price'!M769 -> 29 | AJ10: ='Historical Sale Price'!Q769 -> 72 | AK10: ='Historical Sale Price'!U769 -> 76 | AL10: ='Forward Sale Price'!I313 -> 127 | AM10: ='Forward Sale Price'!M313 -> 122 | AN10: ='Forward Sale Price'!Q313 -> 108 | AO10: ='Forward Sale Price'!U313 -> 105 | AP10: =AVERAGE(B10:AO10) -> 92.615385 | AQ10: =SUMPRODUCT(B$2:AO$2,B10:AO10) -> 92.8 | AS10: Augusta - GA | AT10: Myrtle Beach - SC | AU10: 35.7 | AV10: =RANK(AU10,AU$4:AU$153,-1) -> 7 | AY10: Palm Beach - FL | AZ10: 36.2 | BA10: 7
A11: Austin - TX | B11: ='Asking Rent'!I314 -> 132 | C11: ='Asking Rent'!M314 -> 148 | D11: ='Asking Rent'!Q314 -> 150 | E11: ='Asking Rent'!U314 -> 150 | F11: ='Effective Rent-Forward'!I314 -> 123 | G11: ='Effective Rent-Forward'!N314 -> 148 | H11: ='Effective Rent-Forward'!R314 -> 150 | I11: ='Effective Rent-Forward'!V314 -> 150 | J11: ='Historical Employment'!H465 -> 1 | K11: ='Historical Employment'!D465 -> 3 | L11: ='Forward Employment'!I315 -> 1 | M11: ='Forward Employment'!M315 -> 1 | N11: ='Forward Employment'!Q315 -> 2 | O11: ='Forward Employment'!U315 -> 14 | P11: ='Supply Historical'!C315 -> 139 | Q11: ='Supply Forward'!I314 -> 127 | R11: ='Supply Forward'!M314 -> 132 | S11: ='Supply Forward'!Q314 -> 134 | T11: ='Supply Forward'!U314 -> 134 | U11: ='UPP Historical'!C626 -> 129 | V11: ='Forward UPP'!C620 -> 47 | W11: ='Forward UPP'!F620 | X11: ='Income Growth'!I314 -> 26 | Y11: ='Income Growth'!M314 -> 19 | Z11: ='Income Growth'!Q314 -> 27 | AA11: ='Income Growth'!U314 -> 45 | AB11: ='Historical Population Growth'!I465 -> 3 | AC11: ='Historical Population Growth'!D465 -> 4 | AD11: ='Population Growth Forward'!I314 -> 1 | AE11: ='Population Growth Forward'!M314 -> 1 | AF11: ='Population Growth Forward'!Q314 -> 1 | AG11: ='Population Growth Forward'!U314 -> 1 | AH11: ='Historical Sale Price'!I770 -> 147 | AI11: ='Historical Sale Price'!M770 -> 148 | AJ11: ='Historical Sale Price'!Q770 -> 145 | AK11: ='Historical Sale Price'!U770 -> 126 | AL11: ='Forward Sale Price'!I314 -> 28 | AM11: ='Forward Sale Price'!M314 -> 37 | AN11: ='Forward Sale Price'!Q314 -> 85 | AO11: ='Forward Sale Price'!U314 -> 91 | AP11: =AVERAGE(B11:AO11) -> 75.641026 | AQ11: =SUMPRODUCT(B$2:AO$2,B11:AO11) -> 57.4 | AS11: Austin - TX | AT11: Reno - NV | AU11: 37.5 | AV11: =RANK(AU11,AU$4:AU$153,-1) -> 8 | AY11: Phoenix - AZ | AZ11: 36.3 | BA11: 8
A12: Bakersfield - CA | B12: ='Asking Rent'!I315 -> 19 | C12: ='Asking Rent'!M315 -> 23 | D12: ='Asking Rent'!Q315 -> 20 | E12: ='Asking Rent'!U315 -> 13 | F12: ='Effective Rent-Forward'!I315 -> 19 | G12: ='Effective Rent-Forward'!N315 -> 32 | H12: ='Effective Rent-Forward'!R315 -> 25 | I12: ='Effective Rent-Forward'!V315 -> 17 | J12: ='Historical Employment'!H466 -> 49 | K12: ='Historical Employment'!D466 -> 29 | L12: ='Forward Employment'!I316 -> 50 | M12: ='Forward Employment'!M316 -> 54 | N12: ='Forward Employment'!Q316 -> 51 | O12: ='Forward Employment'!U316 -> 82 | P12: ='Supply Historical'!C316 -> 24 | Q12: ='Supply Forward'!I315 -> 131 | R12: ='Supply Forward'!M315 -> 92 | S12: ='Supply Forward'!Q315 -> 78 | T12: ='Supply Forward'!U315 -> 64 | U12: ='UPP Historical'!C627 -> 24 | V12: ='Forward UPP'!C621 -> 67 | W12: ='Forward UPP'!F621 | X12: ='Income Growth'!I315 -> 17 | Y12: ='Income Growth'!M315 -> 38 | Z12: ='Income Growth'!Q315 -> 38 | AA12: ='Income Growth'!U315 -> 29 | AB12: ='Historical Population Growth'!I466 -> 93 | AC12: ='Historical Population Growth'!D466 -> 110 | AD12: ='Population Growth Forward'!I315 -> 87 | AE12: ='Population Growth Forward'!M315 -> 70 | AF12: ='Population Growth Forward'!Q315 -> 66 | AG12: ='Population Growth Forward'!U315 -> 63 | AH12: ='Historical Sale Price'!I771 -> 111 | AI12: ='Historical Sale Price'!M771 -> 89 | AJ12: ='Historical Sale Price'!Q771 -> 64 | AK12: ='Historical Sale Price'!U771 -> 82 | AL12: ='Forward Sale Price'!I315 -> 26 | AM12: ='Forward Sale Price'!M315 -> 38 | AN12: ='Forward Sale Price'!Q315 -> 36 | AO12: ='Forward Sale Price'!U315 -> 30 | AP12: =AVERAGE(B12:AO12) -> 52.564103 | AQ12: =SUMPRODUCT(B$2:AO$2,B12:AO12) -> 51.2 | AS12: Bakersfield - CA | AT12: Phoenix - AZ | AU12: 37.6 | AV12: =RANK(AU12,AU$4:AU$153,-1) -> 9 | AY12: Tampa - FL | AZ12: 37.3 | BA12: 9
A13: Baltimore - MD | B13: ='Asking Rent'!I316 -> 77 | C13: ='Asking Rent'!M316 -> 78 | D13: ='Asking Rent'!Q316 -> 73 | E13: ='Asking Rent'!U316 -> 69 | F13: ='Effective Rent-Forward'!I316 -> 79 | G13: ='Effective Rent-Forward'!N316 -> 82 | H13: ='Effective Rent-Forward'!R316 -> 62 | I13: ='Effective Rent-Forward'!V316 -> 65 | J13: ='Historical Employment'!H467 -> 108 | K13: ='Historical Employment'!D467 -> 115 | L13: ='Forward Employment'!I317 -> 116 | M13: ='Forward Employment'!M317 -> 113 | N13: ='Forward Employment'!Q317 -> 112 | O13: ='Forward Employment'!U317 -> 138 | P13: ='Supply Historical'!C317 -> 22 | Q13: ='Supply Forward'!I316 -> 53 | R13: ='Supply Forward'!M316 -> 45 | S13: ='Supply Forward'!Q316 -> 52 | T13: ='Supply Forward'!U316 -> 56 | U13: ='UPP Historical'!C628 -> 57 | V13: ='Forward UPP'!C622 -> 73 | W13: ='Forward UPP'!F622 | X13: ='Income Growth'!I316 -> 116 | Y13: ='Income Growth'!M316 -> 125 | Z13: ='Income Growth'!Q316 -> 132 | AA13: ='Income Growth'!U316 -> 135 | AB13: ='Historical Population Growth'!I467 -> 112 | AC13: ='Historical Population Growth'!D467 -> 119 | AD13: ='Population Growth Forward'!I316 -> 106 | AE13: ='Population Growth Forward'!M316 -> 106 | AF13: ='Population Growth Forward'!Q316 -> 104 | AG13: ='Population Growth Forward'!U316 -> 98 | AH13: ='Historical Sale Price'!I772 -> 114 | AI13: ='Historical Sale Price'!M772 -> 120 | AJ13: ='Historical Sale Price'!Q772 -> 109 | AK13: ='Historical Sale Price'!U772 -> 128 | AL13: ='Forward Sale Price'!I316 -> 54 | AM13: ='Forward Sale Price'!M316 -> 61 | AN13: ='Forward Sale Price'!Q316 -> 51 | AO13: ='Forward Sale Price'!U316 -> 58 | AP13: =AVERAGE(B13:AO13) -> 89.564103 | AQ13: =SUMPRODUCT(B$2:AO$2,B13:AO13) -> 82.2 | AS13: Baltimore - MD | AT13: Dallas-Fort Worth - TX | AU13: 40.2 | AV13: =RANK(AU13,AU$4:AU$153,-1) -> 10 | AY13: Charleston - SC | AZ13: 37.5 | BA13: 10
A14: Baton Rouge - LA | B14: ='Asking Rent'!I317 -> 111 | C14: ='Asking Rent'!M317 -> 110 | D14: ='Asking Rent'!Q317 -> 112 | E14: ='Asking Rent'!U317 -> 116 | F14: ='Effective Rent-Forward'!I317 -> 109 | G14: ='Effective Rent-Forward'!N317 -> 120 | H14: ='Effective Rent-Forward'!R317 -> 121 | I14: ='Effective Rent-Forward'!V317 -> 112 | J14: ='Historical Employment'!H468 -> 99 | K14: ='Historical Employment'!D468 -> 82 | L14: ='Forward Employment'!I318 -> 100 | M14: ='Forward Employment'!M318 -> 99 | N14: ='Forward Employment'!Q318 -> 98 | O14: ='Forward Employment'!U318 -> 134 | P14: ='Supply Historical'!C318 -> 59 | Q14: ='Supply Forward'!I317 -> 62 | R14: ='Supply Forward'!M317 -> 41 | S14: ='Supply Forward'!Q317 -> 46 | T14: ='Supply Forward'!U317 -> 52 | U14: ='UPP Historical'!C629 -> 79 | V14: ='Forward UPP'!C623 -> 64 | W14: ='Forward UPP'!F623 | X14: ='Income Growth'!I317 -> 52 | Y14: ='Income Growth'!M317 -> 37 | Z14: ='Income Growth'!Q317 -> 43 | AA14: ='Income Growth'!U317 -> 49 | AB14: ='Historical Population Growth'!I468 -> 100 | AC14: ='Historical Population Growth'!D468 -> 94 | AD14: ='Population Growth Forward'!I317 -> 97 | AE14: ='Population Growth Forward'!M317 -> 100 | AF14: ='Population Growth Forward'!Q317 -> 101 | AG14: ='Population Growth Forward'!U317 -> 102 | AH14: ='Historical Sale Price'!I773 -> 149 | AI14: ='Historical Sale Price'!M773 -> 149 | AJ14: ='Historical Sale Price'!Q773 -> 131 | AK14: ='Historical Sale Price'!U773 -> 138 | AL14: ='Forward Sale Price'!I317 -> 130 | AM14: ='Forward Sale Price'!M317 -> 125 | AN14: ='Forward Sale Price'!Q317 -> 121 | AO14: ='Forward Sale Price'!U317 -> 111 | AP14: =AVERAGE(B14:AO14) -> 96.282051 | AQ14: =SUMPRODUCT(B$2:AO$2,B14:AO14) -> 98.7 | AS14: Baton Rouge - LA | AT14: Salem - OR | AU14: 40.2 | AV14: =RANK(AU14,AU$4:AU$153,-1) -> 10 | AY14: Las Vegas - NV | AZ14: 39 | BA14: 11
A15: Beaumont - TX | B15: ='Asking Rent'!I318 -> 105 | C15: ='Asking Rent'!M318 -> 128 | D15: ='Asking Rent'!Q318 -> 126 | E15: ='Asking Rent'!U318 -> 119 | F15: ='Effective Rent-Forward'!I318 -> 107 | G15: ='Effective Rent-Forward'!N318 -> 123 | H15: ='Effective Rent-Forward'!R318 -> 124 | I15: ='Effective Rent-Forward'!V318 -> 126 | J15: ='Historical Employment'!H469 -> 123 | K15: ='Historical Employment'!D469 -> 27 | L15: ='Forward Employment'!I319 -> 136 | M15: ='Forward Employment'!M319 -> 132 | N15: ='Forward Employment'!Q319 -> 131 | O15: ='Forward Employment'!U319 -> 140 | P15: ='Supply Historical'!C319 -> 37 | Q15: ='Supply Forward'!I318 -> 2 | R15: ='Supply Forward'!M318 -> 8 | S15: ='Supply Forward'!Q318 -> 8 | T15: ='Supply Forward'!U318 -> 9 | U15: ='UPP Historical'!C630 -> 49 | V15: ='Forward UPP'!C624 -> 60 | W15: ='Forward UPP'!F624 | X15: ='Income Growth'!I318 -> 16 | Y15: ='Income Growth'!M318 -> 42 | Z15: ='Income Growth'!Q318 -> 28 | AA15: ='Income Growth'!U318 -> 13 | AB15: ='Historical Population Growth'!I469 -> 124 | AC15: ='Historical Population Growth'!D469 -> 115 | AD15: ='Population Growth Forward'!I318 -> 144 | AE15: ='Population Growth Forward'!M318 -> 146 | AF15: ='Population Growth Forward'!Q318 -> 146 | AG15: ='Population Growth Forward'!U318 -> 148 | AH15: ='Historical Sale Price'!I774 -> 88 | AI15: ='Historical Sale Price'!M774 -> 91 | AJ15: ='Historical Sale Price'!Q774 -> 142 | AK15: ='Historical Sale Price'!U774 -> 137 | AL15: ='Forward Sale Price'!I318 -> 126 | AM15: ='Forward Sale Price'!M318 -> 142 | AN15: ='Forward Sale Price'!Q318 -> 139 | AO15: ='Forward Sale Price'!U318 -> 127 | AP15: =AVERAGE(B15:AO15) -> 95.74359 | AQ15: =SUMPRODUCT(B$2:AO$2,B15:AO15) -> 106.5 | AS15: Beaumont - TX | AT15: Port St. Lucie - FL | AU15: 40.9 | AV15: =RANK(AU15,AU$4:AU$153,-1) -> 12 | AY15: Port St. Lucie - FL | AZ15: 39.2 | BA15: 12
... A153: Youngstown - OH | B153: ='Asking Rent'!I456 -> 11 | C153: ='Asking Rent'!M456 -> 14 | D153: ='Asking Rent'!Q456 -> 22 | E153: ='Asking Rent'!U456 -> 59 | F153: ='Effective Rent-Forward'!I456 -> 11 | G153: ='Effective Rent-Forward'!N456 -> 14 | H153: ='Effective Rent-Forward'!R456 -> 16 | I153: ='Effective Rent-Forward'!V456 -> 46 | J153: ='Historical Employment'!H607 -> 149 | K153: ='Historical Employment'!D607 -> 120 | L153: ='Forward Employment'!I457 -> 149 | M153: ='Forward Employment'!M457 -> 148 | N153: ='Forward Employment'!Q457 -> 148 | O153: ='Forward Employment'!U457 -> 6 | P153: ='Supply Historical'!C457 -> 1 | Q153: ='Supply Forward'!I456 -> 1 | R153: ='Supply Forward'!M456 -> 1 | S153: ='Supply Forward'!Q456 -> 1 | T153: ='Supply Forward'!U456 -> 1 | U153: ='UPP Historical'!C768 -> 14 | V153: ='Forward UPP'!C762 -> 44 | W153: ='Forward UPP'!F762 | X153: ='Income Growth'!I456 -> 142 | Y153: ='Income Growth'!M456 -> 112 | Z153: ='Income Growth'!Q456 -> 110 | AA153: ='Income Growth'!U456 -> 114 | AB153: ='Historical Population Growth'!I607 -> 145 | AC153: ='Historical Population Growth'!D607 -> 142 | AD153: ='Population Growth Forward'!I456 -> 146 | AE153: ='Population Growth Forward'!M456 -> 148 | AF153: ='Population Growth Forward'!Q456 -> 149 | AG153: ='Population Growth Forward'!U456 -> 149 | AH153: ='Historical Sale Price'!I912 -> 31 | AI153: ='Historical Sale Price'!M912 -> 13 | AJ153: ='Historical Sale Price'!Q912 -> 40 | AK153: ='Historical Sale Price'!U912 -> 102 | AL153: ='Forward Sale Price'!I456 -> 66 | AM153: ='Forward Sale Price'!M456 -> 99 | AN153: ='Forward Sale Price'!Q456 -> 104 | AO153: ='Forward Sale Price'!U456 -> 110 | AP153: =AVERAGE(B153:AO153) -> 74.307692 | AQ153: =SUMPRODUCT(B$2:AO$2,B153:AO153) -> 88.7 | AS153: Youngstown - OH | AT153: Pittsburgh - PA | AU153: 130.8 | AV153: =RANK(AU153,AU$4:AU$153,-1) -> 150 | AY153: Pittsburgh - PA | AZ153: 130.2 | BA153: 150

Sheet Asking Rent
A1: Geography Name | B1: 2026 Q2 | C1: 2026 Q3 | D1: 2026 Q4 | E1: 2027 Q1 | F1: 2027 Q2 | G1: 2027 Q3 | H1: 2027 Q4 | I1: 2028 Q1 | J1: 2028 Q2 | K1: 2028 Q3 | L1: 2028 Q4 | M1: 2029 Q1 | N1: 2029 Q2 | O1: 2029 Q3 | P1: 2029 Q4 | Q1: 2030 Q1 | R1: 2030 Q2 | S1: 2030 Q3 | T1: 2030 Q4 | U1: 2031 Q1 | V1: 2031 Q2 | W1: 2031 Q3 | X1: 2031 Q4 | Y1: 2032 Q1 | Z1: 2032 Q2 | AA1: 2032 Q3 | AB1: 2032 Q4 | AC1: 2033 Q1 | AD1: 2033 Q2 | AE1: 2033 Q3 | AF1: 2033 Q4 | AG1: 2034 Q1 | AH1: 2034 Q2 | AI1: 2034 Q3 | AJ1: 2034 Q4 | AK1: 2035 Q1 | AL1: 2035 Q2 | AM1: 2035 Q3 | AN1: 2035 Q4 | AO1: 2036 Q1 | AP1: 2036 Q2
A2: Akron - OH | B2: 1240.4036 | C2: 1233.6185 | D2: 1227.2589 | E2: 1238.692 | F2: 1254.2919 | G2: 1252.4319 | H2: 1250.0265 | I2: 1263.3698 | J2: 1280.375 | K2: 1278.3021 | L2: 1276.9296 | M2: 1291.5654 | N2: 1308.7765 | O2: 1305.6626 | P2: 1302.9535 | Q2: 1316.5756 | R2: 1333.2717 | S2: 1329.6467 | T2: 1326.7729 | U2: 1340.7351 | V2: 1357.8021 | W2: 1354.0579 | X2: 1350.9972 | Y2: 1364.9966 | Z2: 1382.0973 | AA2: 1378.0017 | AB2: 1374.6436 | AC2: 1388.6512 | AD2: 1405.8982 | AE2: 1401.5276 | AF2: 1397.823 | AG2: 1411.7772 | AH2: 1428.9504 | AI2: 1424.198 | AJ2: 1420.2474 | AK2: 1434.5868 | AL2: 1452.1864 | AM2: 1447.574 | AN2: 1443.7225 | AO2: 1458.2443 | AP2: 1476.026
A3: Albany - NY | B3: 1702.4277 | C3: 1697.8229 | D3: 1694.1448 | E3: 1706.9203 | F3: 1724.215 | G3: 1727.6117 | H3: 1730.406 | I3: 1746.4233 | J3: 1765.0231 | K3: 1767.4567 | L3: 1771.0007 | M3: 1788.0859 | N3: 1806.8484 | O3: 1808.4412 | P3: 1810.8365 | Q3: 1826.9164 | R3: 1845.0652 | S3: 1845.9724 | T3: 1848.1315 | U3: 1864.538 | V3: 1883.1591 | W3: 1884.1964 | X3: 1886.3727 | Y3: 1903.0259 | Z3: 1921.8882 | AA3: 1922.7339 | AB3: 1924.7777 | AC3: 1941.6361 | AD3: 1960.6431 | AE3: 1961.3251 | AF3: 1963.2789 | AG3: 1980.1752 | AH3: 1999.3602 | AI3: 1999.8685 | AJ3: 2001.5637 | AK3: 2019.3906 | AL3: 2039.7112 | AM3: 2041.0436 | AN3: 2043.6925 | AO3: 2061.4319 | AP3: 2081.501
A4: Albuquerque - NM | B4: 1307.4371 | C4: 1298.439 | D4: 1281.13 | E4: 1285.5682 | F4: 1300.2292 | G4: 1299.4659 | H4: 1289.5853 | I4: 1299.2369 | J4: 1318.2125 | K4: 1319.9167 | L4: 1313.0132 | M4: 1325.05 | N4: 1344.7439 | O4: 1345.6562 | P4: 1337.4188 | Q4: 1348.7174 | R4: 1368.4222 | S4: 1369.6635 | T4: 1361.8378 | U4: 1373.9783 | V4: 1394.6014 | W4: 1396.2399 | X4: 1388.4624 | Y4: 1400.9684 | Z4: 1422.0568 | AA4: 1423.6989 | AB4: 1415.8239 | AC4: 1428.5623 | AD4: 1450.137 | AE4: 1451.792 | AF4: 1443.7361 | AG4: 1456.7799 | AH4: 1478.7683 | AI4: 1480.4717 | AJ4: 1472.3049 | AK4: 1485.6229 | AL4: 1507.957 | AM4: 1509.5531 | AN4: 1501.0466 | AO4: 1514.8439 | AP4: 1537.9187
A5: Anchorage - AK | B5: 1486.0752 | C5: 1478.5935 | D5: 1466.7797 | E5: 1480.4061 | F5: 1505.8136 | G5: 1502.3762 | H5: 1494.3867 | I5: 1509.8086 | J5: 1536.061 | K5: 1531.6101 | L5: 1524.0853 | M5: 1540.5819 | N5: 1567.3273 | O5: 1562.3215 | P5: 1554.0216 | Q5: 1570.3158 | R5: 1597.1508 | S5: 1592.015 | T5: 1583.7842 | U5: 1600.6866 | V5: 1628.531 | W5: 1623.6908 | X5: 1615.5341 | Y5: 1632.9005 | Z5: 1661.2072 | AA5: 1656.0754 | AB5: 1647.449 | AC5: 1664.9146 | AD5: 1693.6132 | AE5: 1688.2921 | AF5: 1679.5096 | AG5: 1697.3298 | AH5: 1726.5796 | AI5: 1721.0629 | AJ5: 1712.0187 | AK5: 1730.0302 | AL5: 1759.6761 | AM5: 1753.9039 | AN5: 1744.5354 | AO5: 1763.2399 | AP5: 1793.7974
A6: Asheville - NC | B6: 1625.7327 | C6: 1617.1122 | D6: 1603.7047 | E6: 1609.8131 | F6: 1619.2803 | G6: 1620.1074 | H6: 1618.121 | I6: 1630.5057 | J6: 1646.5677 | K6: 1651.108 | L6: 1653.6571 | M6: 1669.5037 | N6: 1686.3016 | O6: 1689.1376 | P6: 1689.324 | Q6: 1703.161 | R6: 1718.7938 | S6: 1721.149 | T6: 1721.4796 | U6: 1736.0328 | V6: 1752.4285 | W6: 1753.1105 | X6: 1753.249 | Y6: 1767.8047 | Z6: 1784.694 | AA6: 1789.7422 | AB6: 1791.1561 | AC6: 1807.3658 | AD6: 1824.5359 | AE6: 1827.4747 | AF6: 1827.6804 | AG6: 1842.8569 | AH6: 1860.47 | AI6: 1863.3875 | AJ6: 1863.9662 | AK6: 1880.0096 | AL6: 1898.0547 | AM6: 1901.0281 | AN6: 1901.6248 | AO6: 1917.5394 | AP6: 1935.4094
A7: Atlanta - GA | B7: 1663.3878 | C7: 1654.6084 | D7: 1638.4788 | E7: 1649.9772 | F7: 1666.9062 | G7: 1665.2767 | H7: 1656.5977 | I7: 1673.2504 | J7: 1693.2383 | K7: 1692.8192 | L7: 1686.8169 | M7: 1706.0771 | N7: 1726.7941 | O7: 1725.3136 | P7: 1717.7375 | Q7: 1736.2059 | R7: 1756.9485 | S7: 1755.7842 | T7: 1748.9603 | U7: 1768.7979 | V7: 1790.9493 | W7: 1790.7024 | X7: 1784.3715 | Y7: 1805.1803 | Z7: 1828.1169 | AA7: 1828.0209 | AB7: 1821.8119 | AC7: 1843.2269 | AD7: 1866.8729 | AE7: 1867.0554 | AF7: 1860.9681 | AG7: 1883.1265 | AH7: 1907.4016 | AI7: 1907.7318 | AJ7: 1901.5492 | AK7: 1924.2521 | AL7: 1949.1415 | AM7: 1949.4523 | AN7: 1943.0514 | AO7: 1966.1766 | AP7: 1991.5393
A8: Augusta - GA | B8: 1294.5615 | C8: 1287.3119 | D8: 1278.6843 | E8: 1285.5447 | F8: 1294.4305 | G8: 1294.3049 | H8: 1293.7098 | I8: 1305.1145 | J8: 1318.0011 | K8: 1319.8837 | L8: 1322.0516 | M8: 1335.6962 | N8: 1349.1176 | O8: 1350.0319 | P8: 1350.8149 | Q8: 1363.3859 | R8: 1376.2286 | S8: 1376.886 | T8: 1377.8716 | U8: 1391.0532 | V8: 1404.4629 | W8: 1403.6394 | X8: 1404.3275 | Y8: 1417.4421 | Z8: 1431.0959 | AA8: 1433.6342 | AB8: 1435.2372 | AC8: 1449.5865 | AD8: 1463.3929 | AE8: 1464.0416 | AF8: 1464.5543 | AG8: 1477.9528 | AH8: 1491.8765 | AI8: 1492.3976 | AJ8: 1493.1442 | AK8: 1507.2843 | AL8: 1521.6058 | AM8: 1522.1774 | AN8: 1522.9916 | AO8: 1537.3259 | AP8: 1551.8026
A9: Austin - TX | B9: 1542.7839 | C9: 1529.1184 | D9: 1511.8419 | E9: 1523.0127 | F9: 1537.2954 | G9: 1529.6493 | H9: 1518.8522 | I9: 1533.0773 | J9: 1551.0532 | K9: 1545.3142 | L9: 1536.962 | M9: 1552.8041 | N9: 1570.1997 | O9: 1562.3054 | P9: 1551.9041 | Q9: 1566.8536 | R9: 1584.4209 | S9: 1577.3431 | T9: 1568.3264 | U9: 1585.1282 | V9: 1604.5334 | W9: 1598.6963 | X9: 1590.5291 | Y9: 1608.3998 | Z9: 1628.7626 | AA9: 1623.42 | AB9: 1615.5853 | AC9: 1634.1112 | AD9: 1655.2427 | AE9: 1650.0563 | AF9: 1642.4427 | AG9: 1661.5438 | AH9: 1683.2301 | AI9: 1678.188 | AJ9: 1670.5137 | AK9: 1690.1024 | AL9: 1712.2155 | AM9: 1707.0446 | AN9: 1699.179 | AO9: 1718.9944 | AP9: 1741.3743
A10: Bakersfield - CA | B10: 1423.249 | C10: 1425.6364 | D10: 1424.5881 | E10: 1430.5605 | F10: 1439.8788 | G10: 1447.1135 | H10: 1451.2612 | I10: 1460.1868 | J10: 1471.0914 | K10: 1478.4036 | L10: 1483.9579 | M10: 1494.301 | N10: 1505.6473 | O10: 1512.5975 | P10: 1517.5477 | Q10: 1527.4979 | R10: 1538.6895 | S10: 1545.8286 | T10: 1551.1978 | U10: 1561.7976 | V10: 1573.7465 | W10: 1581.462 | X10: 1587.2365 | Y10: 1598.2604 | Z10: 1610.6129 | AA10: 1618.521 | AB10: 1624.3409 | AC10: 1635.5625 | AD10: 1648.1165 | AE10: 1656.1877 | AF10: 1662.2041 | AG10: 1673.7184 | AH10: 1686.6017 | AI10: 1694.8671 | AJ10: 1701.0295 | AK10: 1712.8137 | AL10: 1725.9729 | AM10: 1734.3068 | AN10: 1740.4885 | AO10: 1752.4208 | AP10: 1765.7518
A11: Baltimore - MD | B11: 1749.0884 | C11: 1734.203 | D11: 1721.5439 | E11: 1740.1914 | F11: 1761.3492 | G11: 1755.396 | H11: 1750.6152 | I11: 1773.7563 | J11: 1796.806 | K11: 1790.6213 | L11: 1787.5736 | M11: 1813.0176 | N11: 1837.4562 | O11: 1831.0157 | P11: 1827.0322 | Q11: 1852.0453 | R11: 1876.0549 | S11: 1868.7946 | T11: 1864.5339 | U11: 1890.1592 | V11: 1914.8693 | W11: 1907.8862 | X11: 1903.8448 | Y11: 1930.0776 | Z11: 1955.3589 | AA11: 1948.1686 | AB11: 1943.9739 | AC11: 1970.6356 | AD11: 1996.363 | AE11: 1988.9375 | AF11: 1984.4309 | AG11: 2011.6112 | AH11: 2037.7264 | AI11: 2030.0198 | AJ11: 2025.3369 | AK11: 2052.8699 | AL11: 2079.3501 | AM11: 2071.324 | AN11: 2066.3303 | AO11: 2094.2517 | AP11: 2121.0269
A12: Baton Rouge - LA | B12: 1195.0072 | C12: 1188.2496 | D12: 1177.1251 | E12: 1184.678 | F12: 1194.7659 | G12: 1194.15 | H12: 1190.0583 | I12: 1201.5887 | J12: 1215.2399 | K12: 1216.4639 | L12: 1214.8363 | M12: 1228.4266 | N12: 1242.5148 | O12: 1242.7507 | P12: 1239.729 | Q12: 1252.342 | R12: 1265.9445 | S12: 1265.9265 | T12: 1262.9708 | U12: 1276.1145 | V12: 1290.2689 | W12: 1288.9445 | X12: 1285.7112 | Y12: 1298.8246 | Z12: 1313.2526 | AA12: 1314.8984 | AB12: 1312.3427 | AC12: 1326.5094 | AD12: 1341.0781 | AE12: 1341.0856 | AF12: 1337.467 | AG12: 1350.8419 | AH12: 1365.6097 | AI12: 1365.507 | AJ12: 1362.0902 | AK12: 1376.1582 | AL12: 1391.3221 | AM12: 1391.2686 | AN12: 1387.8389 | AO12: 1402.015 | AP12: 1417.2228
A13: Beaumont - TX | B13: 1096.3196 | C13: 1088.1967 | D13: 1082.425 | E13: 1087.093 | F13: 1092.9232 | G13: 1091.4438 | H13: 1091.667 | I13: 1100.4224 | J13: 1109.2875 | K13: 1109.4845 | L13: 1111.9601 | M13: 1122.5115 | N13: 1131.6765 | O13: 1131.1443 | P13: 1132.6836 | Q13: 1142.6211 | R13: 1151.7275 | S13: 1151.5122 | T13: 1153.6198 | U13: 1164.2983 | V13: 1173.9994 | W13: 1174.0764 | X13: 1176.3046 | Y13: 1187.2174 | Z13: 1197.1433 | AA13: 1197.2206 | AB13: 1199.5016 | AC13: 1210.5959 | AD13: 1220.6886 | AE13: 1220.6948 | AF13: 1223.01 | AG13: 1234.3019 | AH13: 1244.5846 | AI13: 1244.6251 | AJ13: 1247.0111 | AK13: 1258.542 | AL13: 1268.9213 | AM13: 1268.8462 | AN13: 1271.0913 | AO13: 1283.1455 | AP13: 1294.1029
... A151: Youngstown - OH | B151: 895.58301 | C151: 896.61676 | D151: 896.95215 | E151: 902.01593 | F151: 907.64014 | G151: 912.15234 | H151: 915.41675 | I151: 921.76617 | J151: 927.97003 | K151: 932.11456 | L151: 935.95953 | M151: 942.96252 | N151: 949.13245 | O151: 952.85394 | P151: 955.98364 | Q151: 962.38043 | R151: 968.16052 | S151: 971.63757 | T151: 974.80054 | U151: 981.44641 | V151: 987.30884 | W151: 990.77686 | X151: 993.89056 | Y151: 1000.4182 | Z151: 1006.2877 | AA151: 1009.7169 | AB151: 1012.7162 | AC151: 1019.1574 | AD151: 1024.9583 | AE151: 1028.2028 | AF151: 1031.0958 | AG151: 1037.5692 | AH151: 1043.3076 | AI151: 1046.4124 | AJ151: 1049.1572 | AK151: 1055.7744 | AL151: 1061.6877 | AM151: 1065.045 | AN151: 1068.0398 | AO151: 1075.0018 | AP151: 1081.1626
E153: 1 | M153: 3 | U153: 5 | AO153: 10
A154: Geography Name | B154: =B1 -> 2026 Q2 | C154: =C1 -> 2026 Q3 | D154: =D1 -> 2026 Q4 | E154: =E1 -> 2027 Q1 | F154: =F1 -> 2027 Q2 | G154: =G1 -> 2027 Q3 | H154: =H1 -> 2027 Q4 | I154: =I1 -> 2028 Q1 | ... AP154: =AP1 -> 2036 Q2
A155: Akron - OH | B155: =B2/$B2 -> 1 | C155: =C2/$B2 -> 0.99452998 | D155: =D2/$B2 -> 0.98940292 | E155: =E2/$B2 -> 0.99862017 | F155: =F2/$B2 -> 1.0111966 | G155: =G2/$B2 -> 1.0096971 | H155: =H2/$B2 -> 1.0077579 | I155: =I2/$B2 -> 1.0185151 | ... AP155: =AP2/$B2 -> 1.1899563
A156: Albany - NY | B156: =B3/$B3 -> 1 | C156: =C3/$B3 -> 0.99729512 | D156: =D3/$B3 -> 0.99513462 | E156: =E3/$B3 -> 1.0026389 | F156: =F3/$B3 -> 1.0127977 | G156: =G3/$B3 -> 1.014793 | H156: =H3/$B3 -> 1.0164343 | I156: =I3/$B3 -> 1.0258429 | ... AP156: =AP3/$B3 -> 1.2226663
A157: Albuquerque - NM | B157: =B4/$B4 -> 1 | C157: =C4/$B4 -> 0.9931177 | D157: =D4/$B4 -> 0.97987886 | E157: =E4/$B4 -> 0.98327346 | F157: =F4/$B4 -> 0.99448701 | G157: =G4/$B4 -> 0.99390319 | H157: =H4/$B4 -> 0.98634595 | I157: =I4/$B4 -> 0.99372804 | ... AP157: =AP4/$B4 -> 1.176285
A158: Anchorage - AK | B158: =B5/$B5 -> 1 | C158: =C5/$B5 -> 0.99496547 | D158: =D5/$B5 -> 0.98701578 | E158: =E5/$B5 -> 0.99618521 | F158: =F5/$B5 -> 1.0132822 | G158: =G5/$B5 -> 1.0109692 | H158: =H5/$B5 -> 1.0055929 | I158: =I5/$B5 -> 1.0159705 | ... AP158: =AP5/$B5 -> 1.2070704
A159: Asheville - NC | B159: =B6/$B6 -> 1 | C159: =C6/$B6 -> 0.99469748 | D159: =D6/$B6 -> 0.98645045 | E159: =E6/$B6 -> 0.99020777 | F159: =F6/$B6 -> 0.99603109 | G159: =G6/$B6 -> 0.99653987 | H159: =H6/$B6 -> 0.99531799 | I159: =I6/$B6 -> 1.002936 | ... AP159: =AP6/$B6 -> 1.1904844
A160: Atlanta - GA | B160: =B7/$B7 -> 1 | C160: =C7/$B7 -> 0.99472197 | D160: =D7/$B7 -> 0.98502511 | E160: =E7/$B7 -> 0.99193775 | F160: =F7/$B7 -> 1.0021152 | G160: =G7/$B7 -> 1.0011356 | H160: =H7/$B7 -> 0.99591787 | I160: =I7/$B7 -> 1.0059292 | ... AP160: =AP7/$B7 -> 1.197279
A161: Augusta - GA | B161: =B8/$B8 -> 1 | C161: =C8/$B8 -> 0.99439993 | D161: =D8/$B8 -> 0.98773546 | E161: =E8/$B8 -> 0.99303483 | F161: =F8/$B8 -> 0.99989882 | G161: =G8/$B8 -> 0.99980179 | H161: =H8/$B8 -> 0.99934211 | I161: =I8/$B8 -> 1.0081518 | ... AP161: =AP8/$B8 -> 1.198709
A162: Austin - TX | B162: =B9/$B9 -> 1 | C162: =C9/$B9 -> 0.99114229 | D162: =D9/$B9 -> 0.97994404 | E162: =E9/$B9 -> 0.9871847 | F162: =F9/$B9 -> 0.99644245 | G162: =G9/$B9 -> 0.9914864 | H162: =H9/$B9 -> 0.98448794 | I162: =I9/$B9 -> 0.99370834 | ... AP162: =AP9/$B9 -> 1.1287221
A163: Bakersfield - CA | B163: =B10/$B10 -> 1 | C163: =C10/$B10 -> 1.0016774 | D163: =D10/$B10 -> 1.0009409 | E163: =E10/$B10 -> 1.0051372 | F163: =F10/$B10 -> 1.0116844 | G163: =G10/$B10 -> 1.0167676 | H163: =H10/$B10 -> 1.0196819 | I163: =I10/$B10 -> 1.0259531 | ... AP163: =AP10/$B10 -> 1.2406485
A164: Baltimore - MD | B164: =B11/$B11 -> 1 | C164: =C11/$B11 -> 0.99148964 | D164: =D11/$B11 -> 0.98425212 | E164: =E11/$B11 -> 0.99491337 | F164: =F11/$B11 -> 1.0070099 | G164: =G11/$B11 -> 1.0036062 | H164: =H11/$B11 -> 1.0008729 | I164: =I11/$B11 -> 1.0141033 | ... AP164: =AP11/$B11 -> 1.212647
A165: Baton Rouge - LA | B165: =B12/$B12 -> 1 | C165: =C12/$B12 -> 0.99434517 | D165: =D12/$B12 -> 0.98503601 | E165: =E12/$B12 -> 0.99135635 | F165: =F12/$B12 -> 0.99979805 | G165: =G12/$B12 -> 0.9992827 | H165: =H12/$B12 -> 0.99585873 | I165: =I12/$B12 -> 1.0055075 | ... AP165: =AP12/$B12 -> 1.1859533
A166: Beaumont - TX | B166: =B13/$B13 -> 1 | C166: =C13/$B13 -> 0.99259073 | D166: =D13/$B13 -> 0.9873262 | E166: =E13/$B13 -> 0.99158406 | F166: =F13/$B13 -> 0.99690203 | G166: =G13/$B13 -> 0.99555264 | H166: =H13/$B13 -> 0.99575618 | I166: =I13/$B13 -> 1.0037423 | ... AP166: =AP13/$B13 -> 1.1804066
... A304: Youngstown - OH | B304: =B151/$B151 -> 1 | C304: =C151/$B151 -> 1.0011543 | D304: =D151/$B151 -> 1.0015288 | E304: =E151/$B151 -> 1.0071829 | F304: =F151/$B151 -> 1.0134629 | G304: =G151/$B151 -> 1.0185012 | H304: =H151/$B151 -> 1.0221462 | I304: =I151/$B151 -> 1.0292359 | ... AP304: =AP151/$B151 -> 1.2072165
A306: Market | B306: 1 | C306: 3 | D306: 5 | E306: 10 | G306: Market | H306: 1 | I306: 1 Year Rank | K306: Market | L306: 3 | M306: 3 Year Rank | O306: Market | P306: 5 | Q306: 5 Year Rank | S306: Market | T306: 10 | U306: 10 Year Rank
A307: Akron - OH | B307: =E155 -> 0.99862017 | C307: =M155 -> 1.0412461 | D307: =U155 -> 1.0808862 | E307: =AO155 -> 1.1756208 | G307: Akron - OH | H307: =B307 -> 0.99862017 | I307: =RANK(H307,H$307:H$456) -> 61 | K307: Akron - OH | L307: =C307 -> 1.0412461 | M307: =RANK(L307,L$307:L$456) -> 62 | O307: Akron - OH | P307: =D307 -> 1.0808862 | Q307: =RANK(P307,P$307:P$456) -> 71 | S307: Akron - OH | T307: =E307 -> 1.1756208 | U307: =RANK(T307,T$307:T$456) -> 113
A308: Albany - NY | B308: =E156 -> 1.0026389 | C308: =M156 -> 1.0503153 | D308: =U156 -> 1.095223 | E308: =AO156 -> 1.2108778 | G308: Albany - NY | H308: =B308 -> 1.0026389 | I308: =RANK(H308,H$307:H$456) -> 31 | K308: Albany - NY | L308: =C308 -> 1.0503153 | M308: =RANK(L308,L$307:L$456) -> 20 | O308: Albany - NY | P308: =D308 -> 1.095223 | Q308: =RANK(P308,P$307:P$456) -> 23 | S308: Albany - NY | T308: =E308 -> 1.2108778 | U308: =RANK(T308,T$307:T$456) -> 37
A309: Albuquerque - NM | B309: =E157 -> 0.98327346 | C309: =M157 -> 1.0134713 | D309: =U157 -> 1.0508943 | E309: =AO157 -> 1.1586361 | G309: Albuquerque - NM | H309: =B309 -> 0.98327346 | I309: =RANK(H309,H$307:H$456) -> 145 | K309: Albuquerque - NM | L309: =C309 -> 1.0134713 | M309: =RANK(L309,L$307:L$456) -> 139 | O309: Albuquerque - NM | P309: =D309 -> 1.0508943 | Q309: =RANK(P309,P$307:P$456) -> 137 | S309: Albuquerque - NM | T309: =E309 -> 1.1586361 | U309: =RANK(T309,T$307:T$456) -> 133
A310: Anchorage - AK | B310: =E158 -> 0.99618521 | C310: =M158 -> 1.0366783 | D310: =U158 -> 1.0771236 | E310: =AO158 -> 1.1865078 | G310: Anchorage - AK | H310: =B310 -> 0.99618521 | I310: =RANK(H310,H$307:H$456) -> 73 | K310: Anchorage - AK | L310: =C310 -> 1.0366783 | M310: =RANK(L310,L$307:L$456) -> 77 | O310: Anchorage - AK | P310: =D310 -> 1.0771236 | Q310: =RANK(P310,P$307:P$456) -> 89 | S310: Anchorage - AK | T310: =E310 -> 1.1865078 | U310: =RANK(T310,T$307:T$456) -> 95
A311: Asheville - NC | B311: =E159 -> 0.99020777 | C311: =M159 -> 1.0269239 | D311: =U159 -> 1.0678464 | E311: =AO159 -> 1.1794925 | G311: Asheville - NC | H311: =B311 -> 0.99020777 | I311: =RANK(H311,H$307:H$456) -> 116 | K311: Asheville - NC | L311: =C311 -> 1.0269239 | M311: =RANK(L311,L$307:L$456) -> 114 | O311: Asheville - NC | P311: =D311 -> 1.0678464 | Q311: =RANK(P311,P$307:P$456) -> 113 | S311: Asheville - NC | T311: =E311 -> 1.1794925 | U311: =RANK(T311,T$307:T$456) -> 106
A312: Atlanta - GA | B312: =E160 -> 0.99193775 | C312: =M160 -> 1.0256641 | D312: =U160 -> 1.0633707 | E312: =AO160 -> 1.1820314 | G312: Atlanta - GA | H312: =B312 -> 0.99193775 | I312: =RANK(H312,H$307:H$456) -> 99 | K312: Atlanta - GA | L312: =C312 -> 1.0256641 | M312: =RANK(L312,L$307:L$456) -> 120 | O312: Atlanta - GA | P312: =D312 -> 1.0633707 | Q312: =RANK(P312,P$307:P$456) -> 124 | S312: Atlanta - GA | T312: =E312 -> 1.1820314 | U312: =RANK(T312,T$307:T$456) -> 101
A313: Augusta - GA | B313: =E161 -> 0.99303483 | C313: =M161 -> 1.031775 | D313: =U161 -> 1.0745362 | E313: =AO161 -> 1.1875264 | G313: Augusta - GA | H313: =B313 -> 0.99303483 | I313: =RANK(H313,H$307:H$456) -> 89 | K313: Augusta - GA | L313: =C313 -> 1.031775 | M313: =RANK(L313,L$307:L$456) -> 96 | O313: Augusta - GA | P313: =D313 -> 1.0745362 | Q313: =RANK(P313,P$307:P$456) -> 97 | S313: Augusta - GA | T313: =E313 -> 1.1875264 | U313: =RANK(T313,T$307:T$456) -> 93
A314: Austin - TX | B314: =E162 -> 0.9871847 | C314: =M162 -> 1.0064948 | D314: =U162 -> 1.0274466 | E314: =AO162 -> 1.1142159 | G314: Austin - TX | H314: =B314 -> 0.9871847 | I314: =RANK(H314,H$307:H$456) -> 132 | K314: Austin - TX | L314: =C314 -> 1.0064948 | M314: =RANK(L314,L$307:L$456) -> 148 | O314: Austin - TX | P314: =D314 -> 1.0274466 | Q314: =RANK(P314,P$307:P$456) -> 150 | S314: Austin - TX | T314: =E314 -> 1.1142159 | U314: =RANK(T314,T$307:T$456) -> 150
A315: Bakersfield - CA | B315: =E163 -> 1.0051372 | C315: =M163 -> 1.0499224 | D315: =U163 -> 1.0973467 | E315: =AO163 -> 1.2312819 | G315: Bakersfield - CA | H315: =B315 -> 1.0051372 | I315: =RANK(H315,H$307:H$456) -> 19 | K315: Bakersfield - CA | L315: =C315 -> 1.0499224 | M315: =RANK(L315,L$307:L$456) -> 23 | O315: Bakersfield - CA | P315: =D315 -> 1.0973467 | Q315: =RANK(P315,P$307:P$456) -> 20 | S315: Bakersfield - CA | T315: =E315 -> 1.2312819 | U315: =RANK(T315,T$307:T$456) -> 13
A316: Baltimore - MD | B316: =E164 -> 0.99491337 | C316: =M164 -> 1.03655 | D316: =U164 -> 1.0806539 | E316: =AO164 -> 1.197339 | G316: Baltimore - MD | H316: =B316 -> 0.99491337 | I316: =RANK(H316,H$307:H$456) -> 77 | K316: Baltimore - MD | L316: =C316 -> 1.03655 | M316: =RANK(L316,L$307:L$456) -> 78 | O316: Baltimore - MD | P316: =D316 -> 1.0806539 | Q316: =RANK(P316,P$307:P$456) -> 73 | S316: Baltimore - MD | T316: =E316 -> 1.197339 | U316: =RANK(T316,T$307:T$456) -> 69
...

Sheet Effective Rent-Forward
A1: Geography Name | B1: Concept Name | C1: 2026 Q2 EST | D1: 2026 Q3 | E1: 2026 Q4 | F1: 2027 Q1 | G1: 2027 Q2 | H1: 2027 Q3 | I1: 2027 Q4 | J1: 2028 Q1 | K1: 2028 Q2 | L1: 2028 Q3 | M1: 2028 Q4 | N1: 2029 Q1 | O1: 2029 Q2 | P1: 2029 Q3 | Q1: 2029 Q4 | R1: 2030 Q1 | S1: 2030 Q2 | T1: 2030 Q3 | U1: 2030 Q4 | V1: 2031 Q1 | W1: 2031 Q2 | X1: 2031 Q3 | Y1: 2031 Q4 | Z1: 2032 Q1 | AA1: 2032 Q2 | AB1: 2032 Q3 | AC1: 2032 Q4 | AD1: 2033 Q1 | AE1: 2033 Q2 | AF1: 2033 Q3 | AG1: 2033 Q4 | AH1: 2034 Q1 | AI1: 2034 Q2 | AJ1: 2034 Q3 | AK1: 2034 Q4 | AL1: 2035 Q1 | AM1: 2035 Q2 | AN1: 2035 Q3 | AO1: 2035 Q4 | AP1: 2036 Q1 | AQ1: 2036 Q2
A2: Akron - OH USA | B2: Market Effective Rent/Unit | C2: 1.33 | D2: 1.32 | E2: 1.32 | F2: 1.33 | G2: 1.34 | H2: 1.34 | I2: 1.34 | J2: 1.35 | K2: 1.37 | L2: 1.37 | M2: 1.37 | N2: 1.38 | O2: 1.4 | P2: 1.4 | Q2: 1.4 | R2: 1.41 | S2: 1.43 | T2: 1.42 | U2: 1.42 | V2: 1.44 | W2: 1.45 | X2: 1.45 | Y2: 1.45 | Z2: 1.46 | AA2: 1.48 | AB2: 1.48 | AC2: 1.47 | AD2: 1.49 | AE2: 1.51 | AF2: 1.5 | AG2: 1.5 | AH2: 1.51 | AI2: 1.53 | AJ2: 1.53 | AK2: 1.52 | AL2: 1.54 | AM2: 1.56 | AN2: 1.55 | AO2: 1.55 | AP2: 1.56 | AQ2: 1.58
A3: Albany - NY USA | B3: Market Effective Rent/Unit | C3: 1.75 | D3: 1.75 | E3: 1.74 | F3: 1.76 | G3: 1.77 | H3: 1.78 | I3: 1.78 | J3: 1.8 | K3: 1.82 | L3: 1.82 | M3: 1.82 | N3: 1.84 | O3: 1.86 | P3: 1.86 | Q3: 1.86 | R3: 1.88 | S3: 1.9 | T3: 1.9 | U3: 1.9 | V3: 1.92 | W3: 1.94 | X3: 1.94 | Y3: 1.94 | Z3: 1.96 | AA3: 1.98 | AB3: 1.98 | AC3: 1.98 | AD3: 2 | AE3: 2.02 | AF3: 2.02 | AG3: 2.02 | AH3: 2.04 | AI3: 2.06 | AJ3: 2.06 | AK3: 2.06 | AL3: 2.08 | AM3: 2.1 | AN3: 2.1 | AO3: 2.1 | AP3: 2.12 | AQ3: 2.14
A4: Albuquerque - NM USA | B4: Market Effective Rent/Unit | C4: 1.58 | D4: 1.57 | E4: 1.55 | F4: 1.55 | G4: 1.57 | H4: 1.57 | I4: 1.56 | J4: 1.57 | K4: 1.59 | L4: 1.59 | M4: 1.58 | N4: 1.6 | O4: 1.62 | P4: 1.62 | Q4: 1.61 | R4: 1.63 | S4: 1.65 | T4: 1.65 | U4: 1.64 | V4: 1.66 | W4: 1.68 | X4: 1.68 | Y4: 1.68 | Z4: 1.69 | AA4: 1.72 | AB4: 1.72 | AC4: 1.71 | AD4: 1.72 | AE4: 1.75 | AF4: 1.75 | AG4: 1.74 | AH4: 1.76 | AI4: 1.78 | AJ4: 1.79 | AK4: 1.78 | AL4: 1.79 | AM4: 1.82 | AN4: 1.82 | AO4: 1.81 | AP4: 1.83 | AQ4: 1.86
A5: Anchorage - AK USA | B5: Market Effective Rent/Unit | C5: 2 | D5: 1.99 | E5: 1.98 | F5: 2 | G5: 2.03 | H5: 2.03 | I5: 2.01 | J5: 2.04 | K5: 2.07 | L5: 2.06 | M5: 2.05 | N5: 2.08 | O5: 2.11 | P5: 2.11 | Q5: 2.09 | R5: 2.12 | S5: 2.15 | T5: 2.15 | U5: 2.13 | V5: 2.16 | W5: 2.2 | X5: 2.19 | Y5: 2.18 | Z5: 2.2 | AA5: 2.24 | AB5: 2.23 | AC5: 2.22 | AD5: 2.24 | AE5: 2.28 | AF5: 2.28 | AG5: 2.26 | AH5: 2.29 | AI5: 2.33 | AJ5: 2.32 | AK5: 2.31 | AL5: 2.33 | AM5: 2.37 | AN5: 2.36 | AO5: 2.35 | AP5: 2.38 | AQ5: 2.42
A6: Asheville - NC USA | B6: Market Effective Rent/Unit | C6: 1.54 | D6: 1.53 | E6: 1.52 | F6: 1.53 | G6: 1.54 | H6: 1.54 | I6: 1.53 | J6: 1.55 | K6: 1.56 | L6: 1.57 | M6: 1.57 | N6: 1.58 | O6: 1.6 | P6: 1.6 | Q6: 1.6 | R6: 1.62 | S6: 1.63 | T6: 1.63 | U6: 1.63 | V6: 1.65 | W6: 1.66 | X6: 1.66 | Y6: 1.66 | Z6: 1.68 | AA6: 1.69 | AB6: 1.7 | AC6: 1.7 | AD6: 1.71 | AE6: 1.73 | AF6: 1.73 | AG6: 1.73 | AH6: 1.75 | AI6: 1.76 | AJ6: 1.77 | AK6: 1.77 | AL6: 1.78 | AM6: 1.8 | AN6: 1.8 | AO6: 1.8 | AP6: 1.82 | AQ6: 1.84
A7: Atlanta - GA USA | B7: Market Effective Rent/Unit | C7: 1.58 | D7: 1.57 | E7: 1.56 | F7: 1.57 | G7: 1.58 | H7: 1.58 | I7: 1.57 | J7: 1.59 | K7: 1.61 | L7: 1.61 | M7: 1.6 | N7: 1.62 | O7: 1.64 | P7: 1.64 | Q7: 1.63 | R7: 1.65 | S7: 1.67 | T7: 1.67 | U7: 1.66 | V7: 1.68 | W7: 1.7 | X7: 1.7 | Y7: 1.7 | Z7: 1.72 | AA7: 1.74 | AB7: 1.74 | AC7: 1.73 | AD7: 1.75 | AE7: 1.77 | AF7: 1.77 | AG7: 1.77 | AH7: 1.79 | AI7: 1.81 | AJ7: 1.81 | AK7: 1.81 | AL7: 1.83 | AM7: 1.85 | AN7: 1.85 | AO7: 1.85 | AP7: 1.87 | AQ7: 1.89
A8: Augusta - GA USA | B8: Market Effective Rent/Unit | C8: 1.3 | D8: 1.29 | E8: 1.28 | F8: 1.29 | G8: 1.3 | H8: 1.3 | I8: 1.3 | J8: 1.31 | K8: 1.32 | L8: 1.33 | M8: 1.33 | N8: 1.34 | O8: 1.36 | P8: 1.36 | Q8: 1.36 | R8: 1.37 | S8: 1.38 | T8: 1.38 | U8: 1.38 | V8: 1.4 | W8: 1.41 | X8: 1.41 | Y8: 1.41 | Z8: 1.42 | AA8: 1.44 | AB8: 1.44 | AC8: 1.44 | AD8: 1.46 | AE8: 1.47 | AF8: 1.47 | AG8: 1.47 | AH8: 1.49 | AI8: 1.5 | AJ8: 1.5 | AK8: 1.5 | AL8: 1.52 | AM8: 1.53 | AN8: 1.53 | AO8: 1.53 | AP8: 1.55 | AQ8: 1.56
A9: Austin - TX USA | B9: Market Effective Rent/Unit | C9: 1.68 | D9: 1.67 | E9: 1.65 | F9: 1.66 | G9: 1.68 | H9: 1.67 | I9: 1.66 | J9: 1.67 | K9: 1.69 | L9: 1.68 | M9: 1.68 | N9: 1.69 | O9: 1.71 | P9: 1.7 | Q9: 1.69 | R9: 1.71 | S9: 1.73 | T9: 1.72 | U9: 1.71 | V9: 1.73 | W9: 1.75 | X9: 1.74 | Y9: 1.73 | Z9: 1.75 | AA9: 1.78 | AB9: 1.77 | AC9: 1.76 | AD9: 1.78 | AE9: 1.8 | AF9: 1.8 | AG9: 1.79 | AH9: 1.81 | AI9: 1.84 | AJ9: 1.83 | AK9: 1.82 | AL9: 1.84 | AM9: 1.87 | AN9: 1.86 | AO9: 1.85 | AP9: 1.87 | AQ9: 1.9
A10: Bakersfield - CA USA | B10: Market Effective Rent/Unit | C10: 1.65 | D10: 1.65 | E10: 1.65 | F10: 1.66 | G10: 1.67 | H10: 1.68 | I10: 1.68 | J10: 1.69 | K10: 1.7 | L10: 1.71 | M10: 1.72 | N10: 1.73 | O10: 1.74 | P10: 1.75 | Q10: 1.76 | R10: 1.77 | S10: 1.78 | T10: 1.79 | U10: 1.8 | V10: 1.81 | W10: 1.82 | X10: 1.83 | Y10: 1.84 | Z10: 1.85 | AA10: 1.87 | AB10: 1.87 | AC10: 1.88 | AD10: 1.89 | AE10: 1.91 | AF10: 1.92 | AG10: 1.93 | AH10: 1.94 | AI10: 1.95 | AJ10: 1.96 | AK10: 1.97 | AL10: 1.98 | AM10: 2 | AN10: 2.01 | AO10: 2.02 | AP10: 2.03 | AQ10: 2.05
A11: Baltimore - MD USA | B11: Market Effective Rent/Unit | C11: 1.91 | D11: 1.9 | E11: 1.88 | F11: 1.9 | G11: 1.93 | H11: 1.92 | I11: 1.92 | J11: 1.94 | K11: 1.97 | L11: 1.96 | M11: 1.96 | N11: 1.98 | O11: 2.01 | P11: 2 | Q11: 2 | R11: 2.03 | S11: 2.05 | T11: 2.04 | U11: 2.04 | V11: 2.07 | W11: 2.1 | X11: 2.09 | Y11: 2.08 | Z11: 2.11 | AA11: 2.14 | AB11: 2.13 | AC11: 2.13 | AD11: 2.16 | AE11: 2.18 | AF11: 2.18 | AG11: 2.17 | AH11: 2.2 | AI11: 2.23 | AJ11: 2.22 | AK11: 2.22 | AL11: 2.25 | AM11: 2.27 | AN11: 2.27 | AO11: 2.26 | AP11: 2.29 | AQ11: 2.32
A12: Baton Rouge - LA USA | B12: Market Effective Rent/Unit | C12: 1.25 | D12: 1.24 | E12: 1.23 | F12: 1.24 | G12: 1.25 | H12: 1.25 | I12: 1.24 | J12: 1.26 | K12: 1.27 | L12: 1.27 | M12: 1.27 | N12: 1.28 | O12: 1.3 | P12: 1.3 | Q12: 1.3 | R12: 1.31 | S12: 1.32 | T12: 1.32 | U12: 1.32 | V12: 1.33 | W12: 1.35 | X12: 1.35 | Y12: 1.34 | Z12: 1.36 | AA12: 1.37 | AB12: 1.37 | AC12: 1.37 | AD12: 1.39 | AE12: 1.4 | AF12: 1.4 | AG12: 1.4 | AH12: 1.41 | AI12: 1.43 | AJ12: 1.43 | AK12: 1.42 | AL12: 1.44 | AM12: 1.45 | AN12: 1.45 | AO12: 1.45 | AP12: 1.47 | AQ12: 1.48
A13: Beaumont - TX USA | B13: Market Effective Rent/Unit | C13: 1.27 | D13: 1.26 | E13: 1.25 | F13: 1.26 | G13: 1.26 | H13: 1.26 | I13: 1.26 | J13: 1.27 | K13: 1.28 | L13: 1.28 | M13: 1.29 | N13: 1.3 | O13: 1.31 | P13: 1.31 | Q13: 1.31 | R13: 1.32 | S13: 1.33 | T13: 1.33 | U13: 1.33 | V13: 1.35 | W13: 1.36 | X13: 1.36 | Y13: 1.36 | Z13: 1.37 | AA13: 1.38 | AB13: 1.38 | AC13: 1.39 | AD13: 1.4 | AE13: 1.41 | AF13: 1.41 | AG13: 1.41 | AH13: 1.43 | AI13: 1.44 | AJ13: 1.44 | AK13: 1.44 | AL13: 1.46 | AM13: 1.47 | AN13: 1.47 | AO13: 1.47 | AP13: 1.48 | AQ13: 1.5
... A151: Youngstown - OH USA | B151: Market Effective Rent/Unit | C151: 1.07 | D151: 1.07 | E151: 1.07 | F151: 1.08 | G151: 1.09 | H151: 1.09 | I151: 1.1 | J151: 1.1 | K151: 1.11 | L151: 1.12 | M151: 1.12 | N151: 1.13 | O151: 1.14 | P151: 1.14 | Q151: 1.14 | R151: 1.15 | S151: 1.16 | T151: 1.16 | U151: 1.17 | V151: 1.18 | W151: 1.18 | X151: 1.19 | Y151: 1.19 | Z151: 1.2 | AA151: 1.2 | AB151: 1.21 | AC151: 1.21 | AD151: 1.22 | AE151: 1.23 | AF151: 1.23 | AG151: 1.23 | AH151: 1.24 | AI151: 1.25 | AJ151: 1.25 | AK151: 1.26 | AL151: 1.26 | AM151: 1.27 | AN151: 1.28 | AO151: 1.28 | AP151: 1.29 | AQ151: 1.3
F153: 1 | N153: 3 | V153: 5 | AP153: 10
A154: Geography Name | B154: Concept Name | C154: =C1 -> 2026 Q2 EST | D154: =D1 -> 2026 Q3 | E154: =E1 -> 2026 Q4 | F154: =F1 -> 2027 Q1 | G154: =G1 -> 2027 Q2 | H154: =H1 -> 2027 Q3 | I154: =I1 -> 2027 Q4 | J154: =J1 -> 2028 Q1 | ... AP154: =AP1 -> 2036 Q1
A155: Akron - OH USA | B155: Market Effective Rent/Unit | C155: =C2/$C2 -> 1 | D155: =D2/$C2 -> 0.9924812 | E155: =E2/$C2 -> 0.9924812 | F155: =F2/$C2 -> 1 | G155: =G2/$C2 -> 1.0075188 | H155: =H2/$C2 -> 1.0075188 | I155: =I2/$C2 -> 1.0075188 | J155: =J2/$C2 -> 1.0150376 | ... AP155: =AP2/$C2 -> 1.1729323
A156: Albany - NY USA | B156: Market Effective Rent/Unit | C156: =C3/$C3 -> 1 | D156: =D3/$C3 -> 1 | E156: =E3/$C3 -> 0.99428571 | F156: =F3/$C3 -> 1.0057143 | G156: =G3/$C3 -> 1.0114286 | H156: =H3/$C3 -> 1.0171429 | I156: =I3/$C3 -> 1.0171429 | J156: =J3/$C3 -> 1.0285714 | ... AP156: =AP3/$C3 -> 1.2114286
A157: Albuquerque - NM USA | B157: Market Effective Rent/Unit | C157: =C4/$C4 -> 1 | D157: =D4/$C4 -> 0.99367089 | E157: =E4/$C4 -> 0.98101266 | F157: =F4/$C4 -> 0.98101266 | G157: =G4/$C4 -> 0.99367089 | H157: =H4/$C4 -> 0.99367089 | I157: =I4/$C4 -> 0.98734177 | J157: =J4/$C4 -> 0.99367089 | ... AP157: =AP4/$C4 -> 1.1582278
A158: Anchorage - AK USA | B158: Market Effective Rent/Unit | C158: =C5/$C5 -> 1 | D158: =D5/$C5 -> 0.995 | E158: =E5/$C5 -> 0.99 | F158: =F5/$C5 -> 1 | G158: =G5/$C5 -> 1.015 | H158: =H5/$C5 -> 1.015 | I158: =I5/$C5 -> 1.005 | J158: =J5/$C5 -> 1.02 | ... AP158: =AP5/$C5 -> 1.19
A159: Asheville - NC USA | B159: Market Effective Rent/Unit | C159: =C6/$C6 -> 1 | D159: =D6/$C6 -> 0.99350649 | E159: =E6/$C6 -> 0.98701299 | F159: =F6/$C6 -> 0.99350649 | G159: =G6/$C6 -> 1 | H159: =H6/$C6 -> 1 | I159: =I6/$C6 -> 0.99350649 | J159: =J6/$C6 -> 1.0064935 | ... AP159: =AP6/$C6 -> 1.1818182
A160: Atlanta - GA USA | B160: Market Effective Rent/Unit | C160: =C7/$C7 -> 1 | D160: =D7/$C7 -> 0.99367089 | E160: =E7/$C7 -> 0.98734177 | F160: =F7/$C7 -> 0.99367089 | G160: =G7/$C7 -> 1 | H160: =H7/$C7 -> 1 | I160: =I7/$C7 -> 0.99367089 | J160: =J7/$C7 -> 1.0063291 | ... AP160: =AP7/$C7 -> 1.1835443
A161: Augusta - GA USA | B161: Market Effective Rent/Unit | C161: =C8/$C8 -> 1 | D161: =D8/$C8 -> 0.99230769 | E161: =E8/$C8 -> 0.98461538 | F161: =F8/$C8 -> 0.99230769 | G161: =G8/$C8 -> 1 | H161: =H8/$C8 -> 1 | I161: =I8/$C8 -> 1 | J161: =J8/$C8 -> 1.0076923 | ... AP161: =AP8/$C8 -> 1.1923077
A162: Austin - TX USA | B162: Market Effective Rent/Unit | C162: =C9/$C9 -> 1 | D162: =D9/$C9 -> 0.99404762 | E162: =E9/$C9 -> 0.98214286 | F162: =F9/$C9 -> 0.98809524 | G162: =G9/$C9 -> 1 | H162: =H9/$C9 -> 0.99404762 | I162: =I9/$C9 -> 0.98809524 | J162: =J9/$C9 -> 0.99404762 | ... AP162: =AP9/$C9 -> 1.1130952
A163: Bakersfield - CA USA | B163: Market Effective Rent/Unit | C163: =C10/$C10 -> 1 | D163: =D10/$C10 -> 1 | E163: =E10/$C10 -> 1 | F163: =F10/$C10 -> 1.0060606 | G163: =G10/$C10 -> 1.0121212 | H163: =H10/$C10 -> 1.0181818 | I163: =I10/$C10 -> 1.0181818 | J163: =J10/$C10 -> 1.0242424 | ... AP163: =AP10/$C10 -> 1.230303
A164: Baltimore - MD USA | B164: Market Effective Rent/Unit | C164: =C11/$C11 -> 1 | D164: =D11/$C11 -> 0.9947644 | E164: =E11/$C11 -> 0.98429319 | F164: =F11/$C11 -> 0.9947644 | G164: =G11/$C11 -> 1.0104712 | H164: =H11/$C11 -> 1.0052356 | I164: =I11/$C11 -> 1.0052356 | J164: =J11/$C11 -> 1.0157068 | ... AP164: =AP11/$C11 -> 1.1989529
A165: Baton Rouge - LA USA | B165: Market Effective Rent/Unit | C165: =C12/$C12 -> 1 | D165: =D12/$C12 -> 0.992 | E165: =E12/$C12 -> 0.984 | F165: =F12/$C12 -> 0.992 | G165: =G12/$C12 -> 1 | H165: =H12/$C12 -> 1 | I165: =I12/$C12 -> 0.992 | J165: =J12/$C12 -> 1.008 | ... AP165: =AP12/$C12 -> 1.176
A166: Beaumont - TX USA | B166: Market Effective Rent/Unit | C166: =C13/$C13 -> 1 | D166: =D13/$C13 -> 0.99212598 | E166: =E13/$C13 -> 0.98425197 | F166: =F13/$C13 -> 0.99212598 | G166: =G13/$C13 -> 0.99212598 | H166: =H13/$C13 -> 0.99212598 | I166: =I13/$C13 -> 0.99212598 | J166: =J13/$C13 -> 1 | ... AP166: =AP13/$C13 -> 1.1653543
... A304: Youngstown - OH USA | B304: Market Effective Rent/Unit | C304: =C151/$C151 -> 1 | D304: =D151/$C151 -> 1 | E304: =E151/$C151 -> 1 | F304: =F151/$C151 -> 1.0093458 | G304: =G151/$C151 -> 1.0186916 | H304: =H151/$C151 -> 1.0186916 | I304: =I151/$C151 -> 1.0280374 | J304: =J151/$C151 -> 1.0280374 | ... AP304: =AP151/$C151 -> 1.2056075
B306: 1 | C306: 3 | D306: 5 | E306: 10 | G306: Market | H306: Index | I306: 1 | L306: Market | M306: Index | N306: 3 | P306: Market | Q306: Index | R306: 5 | T306: Market | U306: Index | V306: 10
A307: =A155 -> Akron - OH USA | B307: =F155 -> 1 | C307: =N155 -> 1.037594 | D307: =V155 -> 1.0827068 | E307: =AP155 -> 1.1729323 | G307: Akron - OH USA | H307: =B307 -> 1 | I307: =RANK(H307,H$307:H$456) -> 33 | L307: Akron - OH USA | M307: =C307 -> 1.037594 | N307: =RANK(M307,M$307:M$456) -> 79 | P307: Akron - OH USA | Q307: =D307 -> 1.0827068 | R307: =RANK(Q307,Q$307:Q$456) -> 69 | T307: Akron - OH USA | U307: =E307 -> 1.1729323 | V307: =RANK(U307,U$307:U$456) -> 114
A308: =A156 -> Albany - NY USA | B308: =F156 -> 1.0057143 | C308: =N156 -> 1.0514286 | D308: =V156 -> 1.0971429 | E308: =AP156 -> 1.2114286 | G308: Albany - NY USA | H308: =B308 -> 1.0057143 | I308: =RANK(H308,H$307:H$456) -> 23 | L308: Albany - NY USA | M308: =C308 -> 1.0514286 | N308: =RANK(M308,M$307:M$456) -> 22 | P308: Albany - NY USA | Q308: =D308 -> 1.0971429 | R308: =RANK(Q308,Q$307:Q$456) -> 24 | T308: Albany - NY USA | U308: =E308 -> 1.2114286 | V308: =RANK(U308,U$307:U$456) -> 34
A309: =A157 -> Albuquerque - NM USA | B309: =F157 -> 0.98101266 | C309: =N157 -> 1.0126582 | D309: =V157 -> 1.0506329 | E309: =AP157 -> 1.1582278 | G309: Albuquerque - NM USA | H309: =B309 -> 0.98101266 | I309: =RANK(H309,H$307:H$456) -> 143 | L309: Albuquerque - NM USA | M309: =C309 -> 1.0126582 | N309: =RANK(M309,M$307:M$456) -> 140 | P309: Albuquerque - NM USA | Q309: =D309 -> 1.0506329 | R309: =RANK(Q309,Q$307:Q$456) -> 137 | T309: Albuquerque - NM USA | U309: =E309 -> 1.1582278 | V309: =RANK(U309,U$307:U$456) -> 134
A310: =A158 -> Anchorage - AK USA | B310: =F158 -> 1 | C310: =N158 -> 1.04 | D310: =V158 -> 1.08 | E310: =AP158 -> 1.19 | G310: Anchorage - AK USA | H310: =B310 -> 1 | I310: =RANK(H310,H$307:H$456) -> 33 | L310: Anchorage - AK USA | M310: =C310 -> 1.04 | N310: =RANK(M310,M$307:M$456) -> 69 | P310: Anchorage - AK USA | Q310: =D310 -> 1.08 | R310: =RANK(Q310,Q$307:Q$456) -> 79 | T310: Anchorage - AK USA | U310: =E310 -> 1.19 | V310: =RANK(U310,U$307:U$456) -> 87
A311: =A159 -> Asheville - NC USA | B311: =F159 -> 0.99350649 | C311: =N159 -> 1.025974 | D311: =V159 -> 1.0714286 | E311: =AP159 -> 1.1818182 | G311: Asheville - NC USA | H311: =B311 -> 0.99350649 | I311: =RANK(H311,H$307:H$456) -> 88 | L311: Asheville - NC USA | M311: =C311 -> 1.025974 | N311: =RANK(M311,M$307:M$456) -> 113 | P311: Asheville - NC USA | Q311: =D311 -> 1.0714286 | R311: =RANK(Q311,Q$307:Q$456) -> 107 | T311: Asheville - NC USA | U311: =E311 -> 1.1818182 | V311: =RANK(U311,U$307:U$456) -> 105
A312: =A160 -> Atlanta - GA USA | B312: =F160 -> 0.99367089 | C312: =N160 -> 1.0253165 | D312: =V160 -> 1.0632911 | E312: =AP160 -> 1.1835443 | G312: Atlanta - GA USA | H312: =B312 -> 0.99367089 | I312: =RANK(H312,H$307:H$456) -> 85 | L312: Atlanta - GA USA | M312: =C312 -> 1.0253165 | N312: =RANK(M312,M$307:M$456) -> 114 | P312: Atlanta - GA USA | Q312: =D312 -> 1.0632911 | R312: =RANK(Q312,Q$307:Q$456) -> 123 | T312: Atlanta - GA USA | U312: =E312 -> 1.1835443 | V312: =RANK(U312,U$307:U$456) -> 103
A313: =A161 -> Augusta - GA USA | B313: =F161 -> 0.99230769 | C313: =N161 -> 1.0307692 | D313: =V161 -> 1.0769231 | E313: =AP161 -> 1.1923077 | G313: Augusta - GA USA | H313: =B313 -> 0.99230769 | I313: =RANK(H313,H$307:H$456) -> 102 | L313: Augusta - GA USA | M313: =C313 -> 1.0307692 | N313: =RANK(M313,M$307:M$456) -> 102 | P313: Augusta - GA USA | Q313: =D313 -> 1.0769231 | R313: =RANK(Q313,Q$307:Q$456) -> 93 | T313: Augusta - GA USA | U313: =E313 -> 1.1923077 | V313: =RANK(U313,U$307:U$456) -> 79
