Workbook

Sheet Summary Sheet
B1: Asking Rent | F1: Effective Rent | J1: Employment | P1: Supply | U1: Units Per Person | X1: Income | AB1: Population | AH1: Sale Price | AQ1: Check: | AU1: PASTE HERE:
A2: Weighting | H2: 0.2 | K2: 0.1 | N2: 0.1 | V2: 0.2 | AC2: 0.1 | AF2: 0.1 | AN2: 0.2 | AQ2: =SUM(B2:AP2) -> 1
A3: Market | B3: Forward 1 | C3: Forward 3 | D3: Forward 5 | E3: Forward 10 | F3: Forward 1 | G3: Forward 3 | H3: Forward 5 | I3: Forward 10 | J3: 10 Yr. Hist | K3: 5 Yr. Hist | L3: Forward 1 | M3: Forward 3 | N3: Forward 5 | O3: Forward 10 | P3: Historical 5 | Q3: Forward 1 | R3: Forward 3 | S3: Forward 5 | T3: Forward 10 | U3: Historical 10 | V3: Forward 5 | W3: Forward 10 | X3: Forward 1 | Y3: Forward 3 | Z3: Forward 5 | AA3: Forward 10 | AB3: 10 Yr. Hist | AC3: 5 Yr. Hist | AD3: Forward 1 | AE3: Forward 3 | AF3: Forward 5 | AG3: Forward 10 | AH3: Historical 1 | AI3: Historical 3 | AJ3: Historical 5 | AK3: Historical 10 | AL3: Forward 1 | AM3: Forward 3 | AN3: Forward 5 | AO3: Forward 10 | AP3: Simple Average | AQ3: Weighted Average | AT3: Market | AU3: Weighted Avg. | AV3: Rank
A4: Akron - OH | B4: ='Asking Rent'!I307 -> 69 | C4: ='Asking Rent'!M307 -> 104 | D4: ='Asking Rent'!Q307 -> 132 | E4: ='Asking Rent'!U307 -> 145 | F4: ='Effective Rent-Forward'!I307 -> 69 | G4: ='Effective Rent-Forward'!N307 -> 104 | H4: ='Effective Rent-Forward'!R307 -> 133 | I4: ='Effective Rent-Forward'!V307 -> 145 | J4: ='Historical Employment'!H4 -> 142 | K4: ='Historical Employment'!D4 -> 139 | L4: ='Forward Employment'!I308 -> 146 | M4: ='Forward Employment'!M308 -> 146 | N4: ='Forward Employment'!Q308 -> 146 | O4: ='Forward Employment'!U308 -> 145 | P4: ='Supply Historical'!G308 -> 26 | Q4: ='Supply Forward'!I307 -> 6 | R4: ='Supply Forward'!M307 -> 15 | S4: ='Supply Forward'!Q307 -> 17 | T4: ='Supply Forward'!U307 -> 18 | U4: ='UPP Historical'!C619 -> 41 | V4: ='Forward UPP'!C613 -> 45 | W4: ='Forward UPP'!F613 -> 40 | X4: ='Income Growth'!I307 -> 149 | Y4: ='Income Growth'!M307 -> 148 | Z4: ='Income Growth'!Q307 -> 142 | AA4: ='Income Growth'!U307 -> 115 | AB4: ='Historical Population Growth'!I3 -> 134 | AC4: ='Historical Population Growth'!D3 -> 123 | AD4: ='Population Growth Forward'!I307 -> 144 | AE4: ='Population Growth Forward'!M307 -> 144 | AF4: ='Population Growth Forward'!Q307 -> 142 | AG4: ='Population Growth Forward'!U307 -> 142 | AH4: ='Historical Sale Price'!I307 -> 12 | AI4: ='Historical Sale Price'!M307 -> 12 | AJ4: ='Historical Sale Price'!Q307 -> 52 | AK4: ='Historical Sale Price'!U307 -> 109 | AL4: ='Forward Sale Price'!I307 -> 64 | AM4: ='Forward Sale Price'!M307 -> 114 | AN4: ='Forward Sale Price'!Q307 -> 137 | AO4: ='Forward Sale Price'!U307 -> 143 | AP4: =AVERAGE(B4:AO4) -> 99.975 | AQ4: =SUMPRODUCT(B$2:AO$2,B4:AO4) -> 118 | AS4: Akron - OH | AT4: Austin - TX | AU4: 17.8 | AV4: =RANK(AU4,AU$4:AU$153,-1) -> 1
A5: Albany - NY | B5: ='Asking Rent'!I308 -> 32 | C5: ='Asking Rent'!M308 -> 23 | D5: ='Asking Rent'!Q308 -> 36 | E5: ='Asking Rent'!U308 -> 81 | F5: ='Effective Rent-Forward'!I308 -> 31 | G5: ='Effective Rent-Forward'!N308 -> 23 | H5: ='Effective Rent-Forward'!R308 -> 36 | I5: ='Effective Rent-Forward'!V308 -> 81 | J5: ='Historical Employment'!H5 -> 122 | K5: ='Historical Employment'!D5 -> 107 | L5: ='Forward Employment'!I309 -> 115 | M5: ='Forward Employment'!M309 -> 117 | N5: ='Forward Employment'!Q309 -> 119 | O5: ='Forward Employment'!U309 -> 121 | P5: ='Supply Historical'!G309 -> 64 | Q5: ='Supply Forward'!I308 -> 30 | R5: ='Supply Forward'!M308 -> 42 | S5: ='Supply Forward'!Q308 -> 55 | T5: ='Supply Forward'!U308 -> 52 | U5: ='UPP Historical'!C620 -> 105 | V5: ='Forward UPP'!C614 -> 80 | W5: ='Forward UPP'!F614 -> 80 | X5: ='Income Growth'!I308 -> 30 | Y5: ='Income Growth'!M308 -> 45 | Z5: ='Income Growth'!Q308 -> 56 | AA5: ='Income Growth'!U308 -> 67 | AB5: ='Historical Population Growth'!I4 -> 107 | AC5: ='Historical Population Growth'!D4 -> 110 | AD5: ='Population Growth Forward'!I308 -> 110 | AE5: ='Population Growth Forward'!M308 -> 114 | AF5: ='Population Growth Forward'!Q308 -> 117 | AG5: ='Population Growth Forward'!U308 -> 119 | AH5: ='Historical Sale Price'!I308 -> 100 | AI5: ='Historical Sale Price'!M308 -> 134 | AJ5: ='Historical Sale Price'!Q308 -> 144 | AK5: ='Historical Sale Price'!U308 -> 139 | AL5: ='Forward Sale Price'!I308 -> 56 | AM5: ='Forward Sale Price'!M308 -> 90 | AN5: ='Forward Sale Price'!Q308 -> 103 | AO5: ='Forward Sale Price'!U308 -> 111 | AP5: =AVERAGE(B5:AO5) -> 82.6 | AQ5: =SUMPRODUCT(B$2:AO$2,B5:AO5) -> 89.1 | AS5: Albany - NY | AT5: Inland Empire - CA | AU5: 19.3 | AV5: =RANK(AU5,AU$4:AU$153,-1) -> 2
A6: Albuquerque - NM | B6: ='Asking Rent'!I309 -> 106 | C6: ='Asking Rent'!M309 -> 116 | D6: ='Asking Rent'!Q309 -> 110 | E6: ='Asking Rent'!U309 -> 103 | F6: ='Effective Rent-Forward'!I309 -> 106 | G6: ='Effective Rent-Forward'!N309 -> 116 | H6: ='Effective Rent-Forward'!R309 -> 110 | I6: ='Effective Rent-Forward'!V309 -> 103 | J6: ='Historical Employment'!H6 -> 74 | K6: ='Historical Employment'!D6 -> 74 | L6: ='Forward Employment'!I310 -> 77 | M6: ='Forward Employment'!M310 -> 86 | N6: ='Forward Employment'!Q310 -> 89 | O6: ='Forward Employment'!U310 -> 100 | P6: ='Supply Historical'!G310 -> 35 | Q6: ='Supply Forward'!I309 -> 104 | R6: ='Supply Forward'!M309 -> 83 | S6: ='Supply Forward'!Q309 -> 76 | T6: ='Supply Forward'!U309 -> 68 | U6: ='UPP Historical'!C621 -> 26 | V6: ='Forward UPP'!C615 -> 92 | W6: ='Forward UPP'!F615 -> 91 | X6: ='Income Growth'!I309 -> 121 | Y6: ='Income Growth'!M309 -> 107 | Z6: ='Income Growth'!Q309 -> 81 | AA6: ='Income Growth'!U309 -> 43 | AB6: ='Historical Population Growth'!I5 -> 101 | AC6: ='Historical Population Growth'!D5 -> 93 | AD6: ='Population Growth Forward'!I309 -> 105 | AE6: ='Population Growth Forward'!M309 -> 104 | AF6: ='Population Growth Forward'!Q309 -> 105 | AG6: ='Population Growth Forward'!U309 -> 108 | AH6: ='Historical Sale Price'!I309 -> 134 | AI6: ='Historical Sale Price'!M309 -> 113 | AJ6: ='Historical Sale Price'!Q309 -> 77 | AK6: ='Historical Sale Price'!U309 -> 90 | AL6: ='Forward Sale Price'!I309 -> 69 | AM6: ='Forward Sale Price'!M309 -> 87 | AN6: ='Forward Sale Price'!Q309 -> 80 | AO6: ='Forward Sale Price'!U309 -> 83 | AP6: =AVERAGE(B6:AO6) -> 91.15 | AQ6: =SUMPRODUCT(B$2:AO$2,B6:AO6) -> 92.5 | AS6: Albuquerque - NM | AT6: Raleigh - NC | AU6: 24.2 | AV6: =RANK(AU6,AU$4:AU$153,-1) -> 3
A7: Anchorage - AK | B7: ='Asking Rent'!I310 -> 97 | C7: ='Asking Rent'!M310 -> 119 | D7: ='Asking Rent'!Q310 -> 120 | E7: ='Asking Rent'!U310 -> 118 | F7: ='Effective Rent-Forward'!I310 -> 97 | G7: ='Effective Rent-Forward'!N310 -> 119 | H7: ='Effective Rent-Forward'!R310 -> 120 | I7: ='Effective Rent-Forward'!V310 -> 118 | J7: ='Historical Employment'!H7 -> 136 | K7: ='Historical Employment'!D7 -> 69 | L7: ='Forward Employment'!I311 -> 123 | M7: ='Forward Employment'!M311 -> 123 | N7: ='Forward Employment'!Q311 -> 122 | O7: ='Forward Employment'!U311 -> 118 | P7: ='Supply Historical'!G311 -> 2 | Q7: ='Supply Forward'!I310 -> 7 | R7: ='Supply Forward'!M310 -> 2 | S7: ='Supply Forward'!Q310 -> 3 | T7: ='Supply Forward'!U310 -> 3 | U7: ='UPP Historical'!C622 -> 2 | V7: ='Forward UPP'!C616 -> 1 | W7: ='Forward UPP'!F616 -> 1 | X7: ='Income Growth'!I310 -> 86 | Y7: ='Income Growth'!M310 -> 126 | Z7: ='Income Growth'!Q310 -> 139 | AA7: ='Income Growth'!U310 -> 146 | AB7: ='Historical Population Growth'!I6 -> 113 | AC7: ='Historical Population Growth'!D6 -> 87 | AD7: ='Population Growth Forward'!I310 -> 71 | AE7: ='Population Growth Forward'!M310 -> 64 | AF7: ='Population Growth Forward'!Q310 -> 64 | AG7: ='Population Growth Forward'!U310 -> 65 | AH7: ='Historical Sale Price'!I310 -> 94 | AI7: ='Historical Sale Price'!M310 -> 112 | AJ7: ='Historical Sale Price'!Q310 -> 126 | AK7: ='Historical Sale Price'!U310 -> 148 | AL7: ='Forward Sale Price'!I310 -> 83 | AM7: ='Forward Sale Price'!M310 -> 127 | AN7: ='Forward Sale Price'!Q310 -> 142 | AO7: ='Forward Sale Price'!U310 -> 131 | AP7: =AVERAGE(B7:AO7) -> 88.6 | AQ7: =SUMPRODUCT(B$2:AO$2,B7:AO7) -> 86.8 | AS7: Anchorage - AK | AT7: San Antonio - TX | AU7: 28 | AV7: =RANK(AU7,AU$4:AU$153,-1) -> 4
A8: Asheville - NC | B8: ='Asking Rent'!I311 -> 117 | C8: ='Asking Rent'!M311 -> 123 | D8: ='Asking Rent'!Q311 -> 102 | E8: ='Asking Rent'!U311 -> 85 | F8: ='Effective Rent-Forward'!I311 -> 117 | G8: ='Effective Rent-Forward'!N311 -> 123 | H8: ='Effective Rent-Forward'!R311 -> 102 | I8: ='Effective Rent-Forward'!V311 -> 85 | J8: ='Historical Employment'!H8 -> 56 | K8: ='Historical Employment'!D8 -> 24 | L8: ='Forward Employment'!I312 -> 61 | M8: ='Forward Employment'!M312 -> 61 | N8: ='Forward Employment'!Q312 -> 59 | O8: ='Forward Employment'!U312 -> 58 | P8: ='Supply Historical'!G312 -> 124 | Q8: ='Supply Forward'!I311 -> 149 | R8: ='Supply Forward'!M311 -> 145 | S8: ='Supply Forward'!Q311 -> 143 | T8: ='Supply Forward'!U311 -> 141 | U8: ='UPP Historical'!C623 -> 147 | V8: ='Forward UPP'!C617 -> 146 | W8: ='Forward UPP'!F617 -> 141 | X8: ='Income Growth'!I311 -> 58 | Y8: ='Income Growth'!M311 -> 81 | Z8: ='Income Growth'!Q311 -> 94 | AA8: ='Income Growth'!U311 -> 88 | AB8: ='Historical Population Growth'!I7 -> 48 | AC8: ='Historical Population Growth'!D7 -> 43 | AD8: ='Population Growth Forward'!I311 -> 49 | AE8: ='Population Growth Forward'!M311 -> 46 | AF8: ='Population Growth Forward'!Q311 -> 46 | AG8: ='Population Growth Forward'!U311 -> 48 | AH8: ='Historical Sale Price'!I311 -> 138 | AI8: ='Historical Sale Price'!M311 -> 31 | AJ8: ='Historical Sale Price'!Q311 -> 16 | AK8: ='Historical Sale Price'!U311 -> 13 | AL8: ='Forward Sale Price'!I311 -> 103 | AM8: ='Forward Sale Price'!M311 -> 49 | AN8: ='Forward Sale Price'!Q311 -> 34 | AO8: ='Forward Sale Price'!U311 -> 36 | AP8: =AVERAGE(B8:AO8) -> 83.25 | AQ8: =SUMPRODUCT(B$2:AO$2,B8:AO8) -> 73.6 | AS8: Asheville - NC | AT8: Reno - NV | AU8: 33.2 | AV8: =RANK(AU8,AU$4:AU$153,-1) -> 5
A9: Atlanta - GA | B9: ='Asking Rent'!I312 -> 146 | C9: ='Asking Rent'!M312 -> 147 | D9: ='Asking Rent'!Q312 -> 145 | E9: ='Asking Rent'!U312 -> 119 | F9: ='Effective Rent-Forward'!I312 -> 146 | G9: ='Effective Rent-Forward'!N312 -> 147 | H9: ='Effective Rent-Forward'!R312 -> 145 | I9: ='Effective Rent-Forward'!V312 -> 119 | J9: ='Historical Employment'!H9 -> 38 | K9: ='Historical Employment'!D9 -> 51 | L9: ='Forward Employment'!I313 -> 34 | M9: ='Forward Employment'!M313 -> 32 | N9: ='Forward Employment'!Q313 -> 31 | O9: ='Forward Employment'!U313 -> 34 | P9: ='Supply Historical'!G313 -> 102 | Q9: ='Supply Forward'!I312 -> 93 | R9: ='Supply Forward'!M312 -> 82 | S9: ='Supply Forward'!Q312 -> 84 | T9: ='Supply Forward'!U312 -> 85 | U9: ='UPP Historical'!C624 -> 69 | V9: ='Forward UPP'!C618 -> 31 | W9: ='Forward UPP'!F618 -> 27 | X9: ='Income Growth'!I312 -> 81 | Y9: ='Income Growth'!M312 -> 91 | Z9: ='Income Growth'!Q312 -> 99 | AA9: ='Income Growth'!U312 -> 106 | AB9: ='Historical Population Growth'!I8 -> 35 | AC9: ='Historical Population Growth'!D8 -> 33 | AD9: ='Population Growth Forward'!I312 -> 22 | AE9: ='Population Growth Forward'!M312 -> 25 | AF9: ='Population Growth Forward'!Q312 -> 23 | AG9: ='Population Growth Forward'!U312 -> 19 | AH9: ='Historical Sale Price'!I312 -> 132 | AI9: ='Historical Sale Price'!M312 -> 98 | AJ9: ='Historical Sale Price'!Q312 -> 39 | AK9: ='Historical Sale Price'!U312 -> 19 | AL9: ='Forward Sale Price'!I312 -> 148 | AM9: ='Forward Sale Price'!M312 -> 149 | AN9: ='Forward Sale Price'!Q312 -> 144 | AO9: ='Forward Sale Price'!U312 -> 121 | AP9: =AVERAGE(B9:AO9) -> 82.275 | AQ9: =SUMPRODUCT(B$2:AO$2,B9:AO9) -> 77.8 | AS9: Atlanta - GA | AT9: Stockton - CA | AU9: 34.8 | AV9: =RANK(AU9,AU$4:AU$153,-1) -> 6
A10: Augusta - GA | B10: ='Asking Rent'!I313 -> 88 | C10: ='Asking Rent'!M313 -> 82 | D10: ='Asking Rent'!Q313 -> 68 | E10: ='Asking Rent'!U313 -> 65 | F10: ='Effective Rent-Forward'!I313 -> 89 | G10: ='Effective Rent-Forward'!N313 -> 82 | H10: ='Effective Rent-Forward'!R313 -> 68 | I10: ='Effective Rent-Forward'!V313 -> 65 | J10: ='Historical Employment'!H10 -> 95 | K10: ='Historical Employment'!D10 -> 147 | L10: ='Forward Employment'!I314 -> 121 | M10: ='Forward Employment'!M314 -> 113 | N10: ='Forward Employment'!Q314 -> 112 | O10: ='Forward Employment'!U314 -> 111 | P10: ='Supply Historical'!G314 -> 121 | Q10: ='Supply Forward'!I313 -> 63 | R10: ='Supply Forward'!M313 -> 52 | S10: ='Supply Forward'!Q313 -> 56 | T10: ='Supply Forward'!U313 -> 58 | U10: ='UPP Historical'!C625 -> 107 | V10: ='Forward UPP'!C619 -> 49 | W10: ='Forward UPP'!F619 -> 54 | X10: ='Income Growth'!I313 -> 102 | Y10: ='Income Growth'!M313 -> 99 | Z10: ='Income Growth'!Q313 -> 91 | AA10: ='Income Growth'!U313 -> 58 | AB10: ='Historical Population Growth'!I9 -> 56 | AC10: ='Historical Population Growth'!D9 -> 54 | AD10: ='Population Growth Forward'!I313 -> 87 | AE10: ='Population Growth Forward'!M313 -> 71 | AF10: ='Population Growth Forward'!Q313 -> 69 | AG10: ='Population Growth Forward'!U313 -> 75 | AH10: ='Historical Sale Price'!I313 -> 14 | AI10: ='Historical Sale Price'!M313 -> 75 | AJ10: ='Historical Sale Price'!Q313 -> 62 | AK10: ='Historical Sale Price'!U313 -> 63 | AL10: ='Forward Sale Price'!I313 -> 122 | AM10: ='Forward Sale Price'!M313 -> 75 | AN10: ='Forward Sale Price'!Q313 -> 60 | AO10: ='Forward Sale Price'!U313 -> 55 | AP10: =AVERAGE(B10:AO10) -> 78.85 | AQ10: =SUMPRODUCT(B$2:AO$2,B10:AO10) -> 73.6 | AS10: Augusta - GA | AT10: Palm Beach - FL | AU10: 36.2 | AV10: =RANK(AU10,AU$4:AU$153,-1) -> 7
A11: Austin - TX | B11: ='Asking Rent'!I314 -> 110 | C11: ='Asking Rent'!M314 -> 20 | D11: ='Asking Rent'!Q314 -> 10 | E11: ='Asking Rent'!U314 -> 10 | F11: ='Effective Rent-Forward'!I314 -> 110 | G11: ='Effective Rent-Forward'!N314 -> 21 | H11: ='Effective Rent-Forward'!R314 -> 10 | I11: ='Effective Rent-Forward'!V314 -> 10 | J11: ='Historical Employment'!H11 -> 1 | K11: ='Historical Employment'!D11 -> 3 | L11: ='Forward Employment'!I315 -> 1 | M11: ='Forward Employment'!M315 -> 1 | N11: ='Forward Employment'!Q315 -> 1 | O11: ='Forward Employment'!U315 -> 2 | P11: ='Supply Historical'!G315 -> 137 | Q11: ='Supply Forward'!I314 -> 126 | R11: ='Supply Forward'!M314 -> 128 | S11: ='Supply Forward'!Q314 -> 131 | T11: ='Supply Forward'!U314 -> 132 | U11: ='UPP Historical'!C626 -> 131 | V11: ='Forward UPP'!C620 -> 72 | W11: ='Forward UPP'!F620 -> 68 | X11: ='Income Growth'!I314 -> 14 | Y11: ='Income Growth'!M314 -> 20 | Z11: ='Income Growth'!Q314 -> 32 | AA11: ='Income Growth'!U314 -> 63 | AB11: ='Historical Population Growth'!I10 -> 3 | AC11: ='Historical Population Growth'!D10 -> 3 | AD11: ='Population Growth Forward'!I314 -> 1 | AE11: ='Population Growth Forward'!M314 -> 1 | AF11: ='Population Growth Forward'!Q314 -> 1 | AG11: ='Population Growth Forward'!U314 -> 1 | AH11: ='Historical Sale Price'!I314 -> 143 | AI11: ='Historical Sale Price'!M314 -> 147 | AJ11: ='Historical Sale Price'!Q314 -> 130 | AK11: ='Historical Sale Price'!U314 -> 104 | AL11: ='Forward Sale Price'!I314 -> 77 | AM11: ='Forward Sale Price'!M314 -> 14 | AN11: ='Forward Sale Price'!Q314 -> 3 | AO11: ='Forward Sale Price'!U314 -> 3 | AP11: =AVERAGE(B11:AO11) -> 49.875 | AQ11: =SUMPRODUCT(B$2:AO$2,B11:AO11) -> 17.8 | AS11: Austin - TX | AT11: Phoenix - AZ | AU11: 36.3 | AV11: =RANK(AU11,AU$4:AU$153,-1) -> 8
A12: Bakersfield - CA | B12: ='Asking Rent'!I315 -> 10 | C12: ='Asking Rent'!M315 -> 9 | D12: ='Asking Rent'!Q315 -> 11 | E12: ='Asking Rent'!U315 -> 12 | F12: ='Effective Rent-Forward'!I315 -> 10 | G12: ='Effective Rent-Forward'!N315 -> 9 | H12: ='Effective Rent-Forward'!R315 -> 11 | I12: ='Effective Rent-Forward'!V315 -> 12 | J12: ='Historical Employment'!H12 -> 60 | K12: ='Historical Employment'!D12 -> 78 | L12: ='Forward Employment'!I316 -> 54 | M12: ='Forward Employment'!M316 -> 57 | N12: ='Forward Employment'!Q316 -> 56 | O12: ='Forward Employment'!U316 -> 53 | P12: ='Supply Historical'!G316 -> 22 | Q12: ='Supply Forward'!I315 -> 54 | R12: ='Supply Forward'!M315 -> 34 | S12: ='Supply Forward'!Q315 -> 29 | T12: ='Supply Forward'!U315 -> 27 | U12: ='UPP Historical'!C627 -> 15 | V12: ='Forward UPP'!C621 -> 14 | W12: ='Forward UPP'!F621 -> 13 | X12: ='Income Growth'!I315 -> 117 | Y12: ='Income Growth'!M315 -> 102 | Z12: ='Income Growth'!Q315 -> 72 | AA12: ='Income Growth'!U315 -> 40 | AB12: ='Historical Population Growth'!I11 -> 88 | AC12: ='Historical Population Growth'!D11 -> 103 | AD12: ='Population Growth Forward'!I315 -> 81 | AE12: ='Population Growth Forward'!M315 -> 69 | AF12: ='Population Growth Forward'!Q315 -> 66 | AG12: ='Population Growth Forward'!U315 -> 63 | AH12: ='Historical Sale Price'!I315 -> 53 | AI12: ='Historical Sale Price'!M315 -> 35 | AJ12: ='Historical Sale Price'!Q315 -> 49 | AK12: ='Historical Sale Price'!U315 -> 65 | AL12: ='Forward Sale Price'!I315 -> 37 | AM12: ='Forward Sale Price'!M315 -> 68 | AN12: ='Forward Sale Price'!Q315 -> 95 | AO12: ='Forward Sale Price'!U315 -> 75 | AP12: =AVERAGE(B12:AO12) -> 48.2 | AQ12: =SUMPRODUCT(B$2:AO$2,B12:AO12) -> 54.3 | AS12: Bakersfield - CA | AT12: Tampa - FL | AU12: 37.3 | AV12: =RANK(AU12,AU$4:AU$153,-1) -> 9
A13: Baltimore - MD | B13: ='Asking Rent'!I316 -> 72 | C13: ='Asking Rent'!M316 -> 68 | D13: ='Asking Rent'!Q316 -> 60 | E13: ='Asking Rent'!U316 -> 53 | F13: ='Effective Rent-Forward'!I316 -> 72 | G13: ='Effective Rent-Forward'!N316 -> 68 | H13: ='Effective Rent-Forward'!R316 -> 60 | I13: ='Effective Rent-Forward'!V316 -> 53 | J13: ='Historical Employment'!H13 -> 125 | K13: ='Historical Employment'!D13 -> 138 | L13: ='Forward Employment'!I317 -> 100 | M13: ='Forward Employment'!M317 -> 106 | N13: ='Forward Employment'!Q317 -> 105 | O13: ='Forward Employment'!U317 -> 108 | P13: ='Supply Historical'!G317 -> 33 | Q13: ='Supply Forward'!I316 -> 43 | R13: ='Supply Forward'!M316 -> 48 | S13: ='Supply Forward'!Q316 -> 50 | T13: ='Supply Forward'!U316 -> 53 | U13: ='UPP Historical'!C628 -> 62 | V13: ='Forward UPP'!C622 -> 61 | W13: ='Forward UPP'!F622 -> 65 | X13: ='Income Growth'!I316 -> 129 | Y13: ='Income Growth'!M316 -> 136 | Z13: ='Income Growth'!Q316 -> 137 | AA13: ='Income Growth'!U316 -> 138 | AB13: ='Historical Population Growth'!I12 -> 109 | AC13: ='Historical Population Growth'!D12 -> 107 | AD13: ='Population Growth Forward'!I316 -> 104 | AE13: ='Population Growth Forward'!M316 -> 99 | AF13: ='Population Growth Forward'!Q316 -> 98 | AG13: ='Population Growth Forward'!U316 -> 98 | AH13: ='Historical Sale Price'!I316 -> 109 | AI13: ='Historical Sale Price'!M316 -> 125 | AJ13: ='Historical Sale Price'!Q316 -> 123 | AK13: ='Historical Sale Price'!U316 -> 140 | AL13: ='Forward Sale Price'!I316 -> 104 | AM13: ='Forward Sale Price'!M316 -> 124 | AN13: ='Forward Sale Price'!Q316 -> 93 | AO13: ='Forward Sale Price'!U316 -> 86 | AP13: =AVERAGE(B13:AO13) -> 91.55 | AQ13: =SUMPRODUCT(B$2:AO$2,B13:AO13) -> 87.6 | AS13: Baltimore - MD | AT13: Charleston - SC | AU13: 37.5 | AV13: =RANK(AU13,AU$4:AU$153,-1) -> 10
A14: Baton Rouge - LA | B14: ='Asking Rent'!I317 -> 112 | C14: ='Asking Rent'!M317 -> 112 | D14: ='Asking Rent'!Q317 -> 98 | E14: ='Asking Rent'!U317 -> 101 | F14: ='Effective Rent-Forward'!I317 -> 112 | G14: ='Effective Rent-Forward'!N317 -> 111 | H14: ='Effective Rent-Forward'!R317 -> 98 | I14: ='Effective Rent-Forward'!V317 -> 101 | J14: ='Historical Employment'!H14 -> 120 | K14: ='Historical Employment'!D14 -> 109 | L14: ='Forward Employment'!I318 -> 66 | M14: ='Forward Employment'!M318 -> 87 | N14: ='Forward Employment'!Q318 -> 90 | O14: ='Forward Employment'!U318 -> 97 | P14: ='Supply Historical'!G318 -> 59 | Q14: ='Supply Forward'!I317 -> 70 | R14: ='Supply Forward'!M317 -> 53 | S14: ='Supply Forward'!Q317 -> 51 | T14: ='Supply Forward'!U317 -> 47 | U14: ='UPP Historical'!C629 -> 80 | V14: ='Forward UPP'!C623 -> 63 | W14: ='Forward UPP'!F623 -> 63 | X14: ='Income Growth'!I317 -> 23 | Y14: ='Income Growth'!M317 -> 26 | Z14: ='Income Growth'!Q317 -> 31 | AA14: ='Income Growth'!U317 -> 46 | AB14: ='Historical Population Growth'!I13 -> 96 | AC14: ='Historical Population Growth'!D13 -> 94 | AD14: ='Population Growth Forward'!I317 -> 103 | AE14: ='Population Growth Forward'!M317 -> 101 | AF14: ='Population Growth Forward'!Q317 -> 100 | AG14: ='Population Growth Forward'!U317 -> 102 | AH14: ='Historical Sale Price'!I317 -> 130 | AI14: ='Historical Sale Price'!M317 -> 66 | AJ14: ='Historical Sale Price'!Q317 -> 65 | AK14: ='Historical Sale Price'!U317 -> 122 | AL14: ='Forward Sale Price'!I317 -> 141 | AM14: ='Forward Sale Price'!M317 -> 115 | AN14: ='Forward Sale Price'!Q317 -> 115 | AO14: ='Forward Sale Price'!U317 -> 101 | AP14: =AVERAGE(B14:AO14) -> 86.925 | AQ14: =SUMPRODUCT(B$2:AO$2,B14:AO14) -> 94.5 | AS14: Baton Rouge - LA | AT14: Las Vegas - NV | AU14: 39 | AV14: =RANK(AU14,AU$4:AU$153,-1) -> 11
A15: Beaumont - TX | B15: ='Asking Rent'!I318 -> 48 | C15: ='Asking Rent'!M318 -> 63 | D15: ='Asking Rent'!Q318 -> 84 | E15: ='Asking Rent'!U318 -> 96 | F15: ='Effective Rent-Forward'!I318 -> 48 | G15: ='Effective Rent-Forward'!N318 -> 63 | H15: ='Effective Rent-Forward'!R318 -> 84 | I15: ='Effective Rent-Forward'!V318 -> 96 | J15: ='Historical Employment'!H15 -> 141 | K15: ='Historical Employment'!D15 -> 143 | L15: ='Forward Employment'!I319 -> 119 | M15: ='Forward Employment'!M319 -> 124 | N15: ='Forward Employment'!Q319 -> 125 | O15: ='Forward Employment'!U319 -> 119 | P15: ='Supply Historical'!G319 -> 42 | Q15: ='Supply Forward'!I318 -> 21 | R15: ='Supply Forward'!M318 -> 6 | S15: ='Supply Forward'!Q318 -> 7 | T15: ='Supply Forward'!U318 -> 10 | U15: ='UPP Historical'!C630 -> 33 | V15: ='Forward UPP'!C624 -> 48 | W15: ='Forward UPP'!F624 -> 42 | X15: ='Income Growth'!I318 -> 50 | Y15: ='Income Growth'!M318 -> 15 | Z15: ='Income Growth'!Q318 -> 5 | AA15: ='Income Growth'!U318 -> 3 | AB15: ='Historical Population Growth'!I14 -> 121 | AC15: ='Historical Population Growth'!D14 -> 109 | AD15: ='Population Growth Forward'!I318 -> 148 | AE15: ='Population Growth Forward'!M318 -> 148 | AF15: ='Population Growth Forward'!Q318 -> 148 | AG15: ='Population Growth Forward'!U318 -> 148 | AH15: ='Historical Sale Price'!I318 -> 101 | AI15: ='Historical Sale Price'!M318 -> 132 | AJ15: ='Historical Sale Price'!Q318 -> 131 | AK15: ='Historical Sale Price'!U318 -> 132 | AL15: ='Forward Sale Price'!I318 -> 112 | AM15: ='Forward Sale Price'!M318 -> 128 | AN15: ='Forward Sale Price'!Q318 -> 128 | AO15: ='Forward Sale Price'!U318 -> 123 | AP15: =AVERAGE(B15:AO15) -> 86.1 | AQ15: =SUMPRODUCT(B$2:AO$2,B15:AO15) -> 104.5 | AS15: Beaumont - TX | AT15: Port St. Lucie - FL | AU15: 39.2 | AV15: =RANK(AU15,AU$4:AU$153,-1) -> 12
... A153: Youngstown - OH | B153: ='Asking Rent'!I456 -> 12 | C153: ='Asking Rent'!M456 -> 46 | D153: ='Asking Rent'!Q456 -> 99 | E153: ='Asking Rent'!U456 -> 131 | F153: ='Effective Rent-Forward'!I456 -> 12 | G153: ='Effective Rent-Forward'!N456 -> 46 | H153: ='Effective Rent-Forward'!R456 -> 99 | I153: ='Effective Rent-Forward'!V456 -> 131 | J153: ='Historical Employment'!H153 -> 150 | K153: ='Historical Employment'!D153 -> 121 | L153: ='Forward Employment'!I457 -> 150 | M153: ='Forward Employment'!M457 -> 150 | N153: ='Forward Employment'!Q457 -> 150 | O153: ='Forward Employment'!U457 -> 150 | P153: ='Supply Historical'!G457 -> 1 | Q153: ='Supply Forward'!I456 -> 1 | R153: ='Supply Forward'!M456 -> 1 | S153: ='Supply Forward'!Q456 -> 1 | T153: ='Supply Forward'!U456 -> 1 | U153: ='UPP Historical'!C768 -> 14 | V153: ='Forward UPP'!C762 -> 37 | W153: ='Forward UPP'!F762 -> 28 | X153: ='Income Growth'!I456 -> 53 | Y153: ='Income Growth'!M456 -> 59 | Z153: ='Income Growth'!Q456 -> 66 | AA153: ='Income Growth'!U456 -> 72 | AB153: ='Historical Population Growth'!I152 -> 149 | AC153: ='Historical Population Growth'!D152 -> 146 | AD153: ='Population Growth Forward'!I456 -> 149 | AE153: ='Population Growth Forward'!M456 -> 149 | AF153: ='Population Growth Forward'!Q456 -> 149 | AG153: ='Population Growth Forward'!U456 -> 149 | AH153: ='Historical Sale Price'!I456 -> 41 | AI153: ='Historical Sale Price'!M456 -> 45 | AJ153: ='Historical Sale Price'!Q456 -> 106 | AK153: ='Historical Sale Price'!U456 -> 137 | AL153: ='Forward Sale Price'!I456 -> 71 | AM153: ='Forward Sale Price'!M456 -> 130 | AN153: ='Forward Sale Price'!Q456 -> 141 | AO153: ='Forward Sale Price'!U456 -> 145 | AP153: =AVERAGE(B153:AO153) -> 87.2 | AQ153: =SUMPRODUCT(B$2:AO$2,B153:AO153) -> 112 | AS153: Youngstown - OH | AT153: Pittsburgh - PA | AU153: 130.2 | AV153: =RANK(AU153,AU$4:AU$153,-1) -> 150

Sheet Asking Rent
A1: Geography Name | B1: 2025 Q2 | C1: 2025 Q3 | D1: 2025 Q4 | E1: 2026 Q1 | F1: 2026 Q2 | G1: 2026 Q3 | H1: 2026 Q4 | I1: 2027 Q1 | J1: 2027 Q2 | K1: 2027 Q3 | L1: 2027 Q4 | M1: 2028 Q1 | N1: 2028 Q2 | O1: 2028 Q3 | P1: 2028 Q4 | Q1: 2029 Q1 | R1: 2029 Q2 | S1: 2029 Q3 | T1: 2029 Q4 | U1: 2030 Q1 | V1: 2030 Q2 | W1: 2030 Q3 | X1: 2030 Q4 | Y1: 2031 Q1 | Z1: 2031 Q2 | AA1: 2031 Q3 | AB1: 2031 Q4 | AC1: 2032 Q1 | AD1: 2032 Q2 | AE1: 2032 Q3 | AF1: 2032 Q4 | AG1: 2033 Q1 | AH1: 2033 Q2 | AI1: 2033 Q3 | AJ1: 2033 Q4 | AK1: 2034 Q1 | AL1: 2034 Q2 | AM1: 2034 Q3 | AN1: 2034 Q4 | AO1: 2035 Q1 | AP1: 2035 Q2
A2: Akron - OH | B2: 1181.4438 | C2: 1183.5099 | D2: 1185.9302 | E2: 1203.77 | F2: 1223.5649 | G2: 1223.8147 | H2: 1224.5104 | I2: 1240.825 | J2: 1259.4132 | K2: 1258.321 | L2: 1257.8435 | M2: 1273.3934 | N2: 1291.2803 | O2: 1288.8624 | P2: 1287.0892 | Q2: 1301.9863 | R2: 1319.3583 | S2: 1316.1497 | T2: 1313.8744 | U2: 1328.6089 | V2: 1346.0155 | W2: 1342.5812 | X2: 1339.9794 | Y2: 1354.8585 | Z2: 1372.3235 | AA2: 1368.4305 | AB2: 1365.533 | AC2: 1380.3046 | AD2: 1397.8439 | AE2: 1393.6801 | AF2: 1390.4014 | AG2: 1405.248 | AH2: 1422.9115 | AI2: 1418.5092 | AJ2: 1415.0214 | AK2: 1429.9717 | AL2: 1447.7803 | AM2: 1443.172 | AN2: 1439.6437 | AO2: 1454.7261 | AP2: 1472.7227
A3: Albany - NY | B3: 1646.1119 | C3: 1653.7125 | D3: 1661.5854 | E3: 1685.197 | F3: 1710.0248 | G3: 1715.6156 | H3: 1721.8296 | I3: 1743.6442 | J3: 1767.2319 | K3: 1771.7297 | L3: 1777.0433 | M3: 1798.5212 | N3: 1821.5039 | O3: 1824.1285 | P3: 1827.6049 | Q3: 1847.6296 | R3: 1869.3401 | S3: 1870.8049 | T3: 1873.5104 | U3: 1893.5956 | V3: 1915.5884 | W3: 1916.9399 | X3: 1919.439 | Y3: 1939.4756 | Z3: 1961.5043 | AA3: 1962.4097 | AB3: 1964.4133 | AC3: 1984.5232 | AD3: 2006.8842 | AE3: 2007.4451 | AF3: 2009.3185 | AG3: 2029.7321 | AH3: 2052.1855 | AI3: 2052.5566 | AJ3: 2054.2629 | AK3: 2074.7092 | AL3: 2097.447 | AM3: 2097.6299 | AN3: 2099.166 | AO3: 2119.8391 | AP3: 2142.8501
A4: Albuquerque - NM | B4: 1285.2117 | C4: 1290.9596 | D4: 1286.4709 | E4: 1303.5227 | F4: 1327.7657 | G4: 1332.5856 | H4: 1326.7356 | I4: 1342.559 | J4: 1367.3704 | K4: 1372.5872 | L4: 1366.8151 | M4: 1382.9978 | N4: 1407.9402 | O4: 1412.2986 | P4: 1405.1768 | Q4: 1420.7965 | R4: 1445.5237 | S4: 1449.2457 | T4: 1441.5178 | U4: 1457.2644 | V4: 1482.4882 | W4: 1486.3278 | X4: 1478.4255 | Y4: 1494.3726 | Z4: 1520.0323 | AA4: 1523.5964 | AB4: 1515.1261 | AC4: 1531.1711 | AD4: 1557.1577 | AE4: 1560.6998 | AF4: 1551.9227 | AG4: 1568.2596 | AH4: 1594.7407 | AI4: 1598.1936 | AJ4: 1588.9463 | AK4: 1605.5714 | AL4: 1632.6106 | AM4: 1635.9061 | AN4: 1626.2964 | AO4: 1643.1624 | AP4: 1670.6794
A5: Anchorage - AK | B5: 1450.4218 | C5: 1452.6047 | D5: 1450.2614 | E5: 1471.7357 | F5: 1502.2538 | G5: 1501.9877 | H5: 1497.1013 | I5: 1517.1682 | J5: 1547.4042 | K5: 1546.2278 | L5: 1540.4519 | M5: 1560.0135 | N5: 1589.6646 | O5: 1587.0461 | P5: 1579.8735 | Q5: 1598.9811 | R5: 1628.6346 | S5: 1625.4921 | T5: 1617.8561 | U5: 1637.2764 | V5: 1667.5887 | W5: 1664.3918 | X5: 1656.5981 | Y5: 1676.4962 | Z5: 1707.5419 | AA5: 1703.9586 | AB5: 1695.6736 | AC5: 1715.7175 | AD5: 1747.1506 | AE5: 1743.5204 | AF5: 1734.9069 | AG5: 1755.2617 | AH5: 1787.26 | AI5: 1783.2264 | AJ5: 1774.2784 | AK5: 1794.9293 | AL5: 1827.4773 | AM5: 1823.3898 | AN5: 1814.2806 | AO5: 1835.2402 | AP5: 1868.3505
A6: Asheville - NC | B6: 1688.0381 | C6: 1692.0095 | D6: 1692.3958 | E6: 1710.4611 | F6: 1731.3979 | G6: 1735.8444 | H6: 1737.0638 | I6: 1756.7344 | J6: 1780.0291 | K6: 1787.2716 | L6: 1790.7267 | M6: 1812.2072 | N6: 1836.55 | O6: 1843.099 | P6: 1845.3124 | Q6: 1866.2141 | R6: 1890.0389 | S6: 1895.9054 | T6: 1897.5527 | U6: 1918.4294 | V6: 1942.6803 | W6: 1948.3218 | X6: 1949.4275 | Y6: 1970.2994 | Z6: 1994.4332 | AA6: 1999.441 | AB6: 2000.1127 | AC6: 2021.0752 | AD6: 2045.3771 | AE6: 2050.2434 | AF6: 2050.3232 | AG6: 2071.4089 | AH6: 2096.1265 | AI6: 2100.6985 | AJ6: 2100.5676 | AK6: 2121.7695 | AL6: 2146.6804 | AM6: 2151.1582 | AN6: 2150.6001 | AO6: 2172.1147 | AP6: 2197.2029
A7: Atlanta - GA | B7: 1668.8685 | C7: 1666.6951 | D7: 1658.1897 | E7: 1675.6898 | F7: 1697.3202 | G7: 1695.5814 | H7: 1689.7577 | I7: 1712.8566 | J7: 1740.6056 | K7: 1743.7012 | L7: 1740.3181 | M7: 1764.6973 | N7: 1792.3401 | O7: 1793.7581 | P7: 1788.5753 | Q7: 1812.2827 | R7: 1839.6359 | S7: 1840.5129 | T7: 1834.9227 | U7: 1859.3296 | V7: 1887.6549 | W7: 1888.7731 | X7: 1883.2334 | Y7: 1908.3062 | Z7: 1937.2167 | AA7: 1938.1782 | AB7: 1932.1152 | AC7: 1957.4738 | AD7: 1986.7786 | AE7: 1987.3904 | AF7: 1980.9919 | AG7: 2006.8497 | AH7: 2036.7426 | AI7: 2037.1945 | AJ7: 2030.4611 | AK7: 2056.7949 | AL7: 2087.4668 | AM7: 2087.7285 | AN7: 2080.6213 | AO7: 2107.4224 | AP7: 2138.6787
A8: Augusta - GA | B8: 1262.0284 | C8: 1264.2003 | D8: 1267.0104 | E8: 1281.8507 | F8: 1297.3851 | G8: 1300.2252 | H8: 1303.7611 | I8: 1319.8311 | J8: 1337.2474 | K8: 1342.0171 | L8: 1347.0704 | M8: 1364.334 | N8: 1381.9805 | O8: 1385.62 | P8: 1389.3722 | Q8: 1405.7076 | R8: 1422.5912 | S8: 1425.4669 | T8: 1428.6906 | U8: 1445.0139 | V8: 1462.1245 | W8: 1464.8264 | X8: 1467.7439 | Y8: 1484.1027 | Z8: 1501.104 | AA8: 1503.2909 | AB8: 1505.8516 | AC8: 1522.2042 | AD8: 1539.2106 | AE8: 1541.0922 | AF8: 1543.2124 | AG8: 1559.5964 | AH8: 1576.7915 | AI8: 1578.3929 | AJ8: 1580.3976 | AK8: 1596.8911 | AL8: 1614.2642 | AM8: 1615.8162 | AN8: 1617.6328 | AO8: 1634.45 | AP8: 1651.9359
A9: Austin - TX | B9: 1597.6477 | C9: 1592.8553 | D9: 1591.5516 | E9: 1620.1384 | F9: 1650.9556 | G9: 1652.9717 | H9: 1653.4624 | I9: 1683.1823 | J9: 1716.4048 | K9: 1718.5039 | L9: 1717.6946 | M9: 1746.5939 | N9: 1778.5515 | O9: 1777.8719 | P9: 1774.2546 | Q9: 1801.6464 | R9: 1832.423 | S9: 1830.2473 | T9: 1825.4072 | U9: 1852.9758 | V9: 1884.4227 | W9: 1882.076 | X9: 1877.1348 | Y9: 1905.55 | Z9: 1937.7623 | AA9: 1935.1876 | AB9: 1929.7683 | AC9: 1958.458 | AD9: 1991.2334 | AE9: 1988.1831 | AF9: 1982.2109 | AG9: 2011.5001 | AH9: 2044.9821 | AI9: 2041.6195 | AJ9: 2035.4717 | AK9: 2065.374 | AL9: 2099.5808 | AM9: 2095.896 | AN9: 2089.3616 | AO9: 2120.0615 | AP9: 2154.9741
A10: Bakersfield - CA | B10: 1397.2712 | C10: 1410.3289 | D10: 1420.5657 | E10: 1436.0504 | F10: 1451.2557 | G10: 1462.2244 | H10: 1470.7241 | I10: 1484.8682 | J10: 1499.4886 | K10: 1509.9845 | L10: 1518.1322 | M10: 1531.726 | N10: 1545.4661 | O10: 1554.9552 | P10: 1562.0129 | Q10: 1575.0054 | R10: 1588.4458 | S10: 1597.8271 | T10: 1604.8923 | U10: 1618.2185 | V10: 1632.0356 | W10: 1641.6813 | X10: 1648.9426 | Y10: 1662.635 | Z10: 1676.8323 | AA10: 1686.5768 | AB10: 1693.901 | AC10: 1707.8352 | AD10: 1722.2887 | AE10: 1732.3401 | AF10: 1739.6975 | AG10: 1753.8375 | AH10: 1768.5112 | AI10: 1778.6594 | AJ10: 1786.2196 | AK10: 1800.7794 | AL10: 1815.8899 | AM10: 1826.3473 | AN10: 1834.0553 | AO10: 1848.7223 | AP10: 1863.9365
A11: Baltimore - MD | B11: 1748.9147 | C11: 1748.109 | D11: 1749.6179 | E11: 1781.2981 | F11: 1811.5752 | G11: 1809.3715 | H11: 1808.9753 | I11: 1837.5344 | J11: 1866.8435 | K11: 1863.7504 | L11: 1863.0819 | M11: 1893.9386 | N11: 1924.8776 | O11: 1921.4703 | P11: 1919.8044 | Q11: 1950.4403 | R11: 1981.2961 | S11: 1976.9767 | T11: 1974.8506 | U11: 2006.1554 | V11: 2037.4927 | W11: 2032.8502 | X11: 2030.2639 | Y11: 2061.8428 | Z11: 2093.2129 | AA11: 2087.4014 | AB11: 2083.7219 | AC11: 2115.0955 | AD11: 2146.4329 | AE11: 2139.842 | AF11: 2135.6399 | AG11: 2167.3918 | AH11: 2199.3076 | AI11: 2192.3484 | AJ11: 2187.835 | AK11: 2220.3635 | AL11: 2252.8374 | AM11: 2245.4861 | AN11: 2240.6375 | AO11: 2273.7427 | AP11: 2306.7722
A12: Baton Rouge - LA | B12: 1198.8907 | C12: 1201.8524 | D12: 1201.1544 | E12: 1215.4435 | F12: 1231.4956 | G12: 1234.9979 | H12: 1234.9025 | I12: 1250.2343 | J12: 1268.001 | K12: 1273.2565 | L12: 1274.475 | M12: 1290.8325 | N12: 1308.8898 | O12: 1313.2108 | P12: 1313.1548 | Q12: 1328.6899 | R12: 1346.1351 | S12: 1349.7214 | T12: 1349.0078 | U12: 1364.4596 | V12: 1382.0717 | W12: 1385.4978 | X12: 1384.3705 | Y12: 1399.8458 | Z12: 1417.3605 | AA12: 1420.3002 | AB12: 1418.6978 | AC12: 1434.13 | AD12: 1451.6715 | AE12: 1454.4126 | AF12: 1452.3593 | AG12: 1467.9071 | AH12: 1485.7524 | AI12: 1488.2946 | AJ12: 1486.0099 | AK12: 1501.6023 | AL12: 1519.5109 | AM12: 1521.9005 | AN12: 1519.2561 | AO12: 1535.0536 | AP12: 1553.088
A13: Beaumont - TX | B13: 1069.5784 | C13: 1073.2943 | D13: 1079.2769 | E13: 1092.9639 | F13: 1105.1907 | G13: 1107.9957 | H13: 1113.1388 | I13: 1125.7837 | J13: 1138.1061 | K13: 1141.1575 | L13: 1146.6017 | M13: 1159.4674 | N13: 1171.6294 | O13: 1173.8405 | P13: 1178.427 | Q13: 1190.7153 | R13: 1202.4325 | S13: 1204.077 | T13: 1208.4076 | U13: 1220.7537 | V13: 1232.5823 | W13: 1234.1947 | X13: 1238.5616 | Y13: 1251.0216 | Z13: 1263.0035 | AA13: 1264.3788 | AB13: 1268.5864 | AC13: 1281.1161 | AD13: 1293.0994 | AE13: 1294.3344 | AF13: 1298.4822 | AG13: 1311.0754 | AH13: 1323.1626 | AI13: 1324.2325 | AJ13: 1328.292 | AK13: 1341.1989 | AL13: 1353.589 | AM13: 1354.5085 | AN13: 1358.4886 | AO13: 1371.5199 | AP13: 1383.9822
... A151: Youngstown - OH | B151: 868.98279 | C151: 876.1004 | D151: 883.13538 | E151: 892.30817 | F151: 900.91772 | G151: 906.77289 | H151: 912.62006 | I151: 920.53406 | J151: 928.13013 | K151: 933.24261 | L151: 938.42731 | M151: 945.66339 | N151: 952.54718 | O151: 956.77185 | P151: 961.06256 | Q151: 967.68793 | R151: 974.06732 | S151: 977.91321 | T151: 981.95831 | U151: 988.36658 | V151: 994.61609 | W151: 998.3642 | X151: 1002.281 | Y151: 1008.7376 | Z151: 1014.8633 | AA151: 1018.3132 | AB151: 1022.0339 | AC151: 1028.2339 | AD151: 1034.2615 | AE151: 1037.6866 | AF151: 1041.2152 | AG151: 1047.356 | AH151: 1053.3179 | AI151: 1056.626 | AJ151: 1060.1024 | AK151: 1066.2634 | AL151: 1072.2408 | AM151: 1075.4388 | AN151: 1078.9 | AO151: 1084.9888 | AP151: 1090.8849
E153: 1 | M153: 3 | U153: 5 | AO153: 10
A154: Geography Name | B154: =B1 -> 2025 Q2 | C154: =C1 -> 2025 Q3 | D154: =D1 -> 2025 Q4 | E154: =E1 -> 2026 Q1 | F154: =F1 -> 2026 Q2 | G154: =G1 -> 2026 Q3 | H154: =H1 -> 2026 Q4 | I154: =I1 -> 2027 Q1 | ... AP154: =AP1 -> 2035 Q2
A155: Akron - OH | B155: =B2/$B2 -> 1 | C155: =C2/$B2 -> 1.0017487 | D155: =D2/$B2 -> 1.0037973 | E155: =E2/$B2 -> 1.0188974 | F155: =F2/$B2 -> 1.0356522 | G155: =G2/$B2 -> 1.0358636 | H155: =H2/$B2 -> 1.0364525 | I155: =I2/$B2 -> 1.0502615 | ... AP155: =AP2/$B2 -> 1.2465448
A156: Albany - NY | B156: =B3/$B3 -> 1 | C156: =C3/$B3 -> 1.0046173 | D156: =D3/$B3 -> 1.0094 | E156: =E3/$B3 -> 1.0237439 | F156: =F3/$B3 -> 1.0388265 | G156: =G3/$B3 -> 1.0422229 | H156: =H3/$B3 -> 1.0459979 | I156: =I3/$B3 -> 1.0592501 | ... AP156: =AP3/$B3 -> 1.3017645
A157: Albuquerque - NM | B157: =B4/$B4 -> 1 | C157: =C4/$B4 -> 1.0044724 | D157: =D4/$B4 -> 1.0009798 | E157: =E4/$B4 -> 1.0142475 | F157: =F4/$B4 -> 1.0331106 | G157: =G4/$B4 -> 1.0368608 | H157: =H4/$B4 -> 1.032309 | I157: =I4/$B4 -> 1.0446209 | ... AP157: =AP4/$B4 -> 1.2999255
A158: Anchorage - AK | B158: =B5/$B5 -> 1 | C158: =C5/$B5 -> 1.0015051 | D158: =D5/$B5 -> 0.99988941 | E158: =E5/$B5 -> 1.014695 | F158: =F5/$B5 -> 1.0357358 | G158: =G5/$B5 -> 1.0355524 | H158: =H5/$B5 -> 1.0321834 | I158: =I5/$B5 -> 1.0460187 | ... AP158: =AP5/$B5 -> 1.2881429
A159: Asheville - NC | B159: =B6/$B6 -> 1 | C159: =C6/$B6 -> 1.0023527 | D159: =D6/$B6 -> 1.0025815 | E159: =E6/$B6 -> 1.0132835 | F159: =F6/$B6 -> 1.0256865 | G159: =G6/$B6 -> 1.0283206 | H159: =H6/$B6 -> 1.029043 | I159: =I6/$B6 -> 1.0406959 | ... AP159: =AP6/$B6 -> 1.3016311
A160: Atlanta - GA | B160: =B7/$B7 -> 1 | C160: =C7/$B7 -> 0.99869764 | D160: =D7/$B7 -> 0.99360115 | E160: =E7/$B7 -> 1.0040874 | F160: =F7/$B7 -> 1.0170485 | G160: =G7/$B7 -> 1.0160066 | H160: =H7/$B7 -> 1.012517 | I160: =I7/$B7 -> 1.026358 | ... AP160: =AP7/$B7 -> 1.2815142
A161: Augusta - GA | B161: =B8/$B8 -> 1 | C161: =C8/$B8 -> 1.0017209 | D161: =D8/$B8 -> 1.0039476 | E161: =E8/$B8 -> 1.0157067 | F161: =F8/$B8 -> 1.0280158 | G161: =G8/$B8 -> 1.0302662 | H161: =H8/$B8 -> 1.0330679 | I161: =I8/$B8 -> 1.0458014 | ... AP161: =AP8/$B8 -> 1.308953
A162: Austin - TX | B162: =B9/$B9 -> 1 | C162: =C9/$B9 -> 0.99700037 | D162: =D9/$B9 -> 0.99618435 | E162: =E9/$B9 -> 1.0140774 | F162: =F9/$B9 -> 1.0333665 | G162: =G9/$B9 -> 1.0346284 | H162: =H9/$B9 -> 1.0349355 | I162: =I9/$B9 -> 1.0535378 | ... AP162: =AP9/$B9 -> 1.3488419
A163: Bakersfield - CA | B163: =B10/$B10 -> 1 | C163: =C10/$B10 -> 1.0093451 | D163: =D10/$B10 -> 1.0166714 | E163: =E10/$B10 -> 1.0277535 | F163: =F10/$B10 -> 1.0386357 | G163: =G10/$B10 -> 1.0464857 | H163: =H10/$B10 -> 1.0525688 | I163: =I10/$B10 -> 1.0626914 | ... AP163: =AP10/$B10 -> 1.3339833
A164: Baltimore - MD | B164: =B11/$B11 -> 1 | C164: =C11/$B11 -> 0.99953933 | D164: =D11/$B11 -> 1.0004021 | E164: =E11/$B11 -> 1.0185163 | F164: =F11/$B11 -> 1.0358282 | G164: =G11/$B11 -> 1.0345682 | H164: =H11/$B11 -> 1.0343417 | I164: =I11/$B11 -> 1.0506713 | ... AP164: =AP11/$B11 -> 1.3189736
A165: Baton Rouge - LA | B165: =B12/$B12 -> 1 | C165: =C12/$B12 -> 1.0024703 | D165: =D12/$B12 -> 1.0018881 | E165: =E12/$B12 -> 1.0138067 | F165: =F12/$B12 -> 1.0271959 | G165: =G12/$B12 -> 1.0301172 | H165: =H12/$B12 -> 1.0300375 | I165: =I12/$B12 -> 1.0428258 | ... AP165: =AP12/$B12 -> 1.2954375
A166: Beaumont - TX | B166: =B13/$B13 -> 1 | C166: =C13/$B13 -> 1.0034742 | D166: =D13/$B13 -> 1.0090676 | E166: =E13/$B13 -> 1.0218642 | F166: =F13/$B13 -> 1.0332956 | G166: =G13/$B13 -> 1.0359182 | H166: =H13/$B13 -> 1.0407267 | I166: =I13/$B13 -> 1.052549 | ... AP166: =AP13/$B13 -> 1.2939512
... A304: Youngstown - OH | B304: =B151/$B151 -> 1 | C304: =C151/$B151 -> 1.0081907 | D304: =D151/$B151 -> 1.0162864 | E304: =E151/$B151 -> 1.0268422 | F304: =F151/$B151 -> 1.0367498 | G304: =G151/$B151 -> 1.0434877 | H304: =H151/$B151 -> 1.0502165 | I304: =I151/$B151 -> 1.0593237 | ... AP304: =AP151/$B151 -> 1.2553585
A306: Market | B306: 1 | C306: 3 | D306: 5 | E306: 10 | G306: Market | H306: 1 | I306: 1 Year Rank | K306: Market | L306: 3 | M306: 3 Year Rank | O306: Market | P306: 5 | Q306: 5 Year Rank | S306: Market | T306: 10 | U306: 10 Year Rank
A307: Akron - OH | B307: =E155 -> 1.0188974 | C307: =M155 -> 1.0778281 | D307: =U155 -> 1.1245637 | E307: =AO155 -> 1.2313121 | G307: Akron - OH | H307: 1.0188974 | I307: =RANK(H307,H$307:H$456) -> 69 | K307: Akron - OH | L307: 1.0778281 | M307: =RANK(L307,L$307:L$456) -> 104 | O307: Akron - OH | P307: 1.1245637 | Q307: =RANK(P307,P$307:P$456) -> 132 | S307: Akron - OH | T307: 1.2313121 | U307: =RANK(T307,T$307:T$456) -> 145
A308: Albany - NY | B308: =E156 -> 1.0237439 | C308: =M156 -> 1.0925874 | D308: =U156 -> 1.1503444 | E308: =AO156 -> 1.2877855 | G308: Albany - NY | H308: 1.0237439 | I308: =RANK(H308,H$307:H$456) -> 32 | K308: Albany - NY | L308: 1.0925874 | M308: =RANK(L308,L$307:L$456) -> 23 | O308: Albany - NY | P308: 1.1503444 | Q308: =RANK(P308,P$307:P$456) -> 36 | S308: Albany - NY | T308: 1.2877855 | U308: =RANK(T308,T$307:T$456) -> 81
A309: Albuquerque - NM | B309: =E157 -> 1.0142475 | C309: =M157 -> 1.0760856 | D309: =U157 -> 1.1338711 | E309: =AO157 -> 1.278515 | G309: Albuquerque - NM | H309: 1.0142475 | I309: =RANK(H309,H$307:H$456) -> 106 | K309: Albuquerque - NM | L309: 1.0760856 | M309: =RANK(L309,L$307:L$456) -> 116 | O309: Albuquerque - NM | P309: 1.1338711 | Q309: =RANK(P309,P$307:P$456) -> 110 | S309: Albuquerque - NM | T309: 1.278515 | U309: =RANK(T309,T$307:T$456) -> 103
A310: Anchorage - AK | B310: =E158 -> 1.014695 | C310: =M158 -> 1.0755586 | D310: =U158 -> 1.1288278 | E310: =AO158 -> 1.2653149 | G310: Anchorage - AK | H310: 1.014695 | I310: =RANK(H310,H$307:H$456) -> 97 | K310: Anchorage - AK | L310: 1.0755586 | M310: =RANK(L310,L$307:L$456) -> 119 | O310: Anchorage - AK | P310: 1.1288278 | Q310: =RANK(P310,P$307:P$456) -> 120 | S310: Anchorage - AK | T310: 1.2653149 | U310: =RANK(T310,T$307:T$456) -> 118
A311: Asheville - NC | B311: =E159 -> 1.0132835 | C311: =M159 -> 1.0735582 | D311: =U159 -> 1.1364847 | E311: =AO159 -> 1.2867688 | G311: Asheville - NC | H311: 1.0132835 | I311: =RANK(H311,H$307:H$456) -> 117 | K311: Asheville - NC | L311: 1.0735582 | M311: =RANK(L311,L$307:L$456) -> 123 | O311: Asheville - NC | P311: 1.1364847 | Q311: =RANK(P311,P$307:P$456) -> 102 | S311: Asheville - NC | T311: 1.2867688 | U311: =RANK(T311,T$307:T$456) -> 85
A312: Atlanta - GA | B312: =E160 -> 1.0040874 | C312: =M160 -> 1.0574214 | D312: =U160 -> 1.1141259 | E312: =AO160 -> 1.2627851 | G312: Atlanta - GA | H312: 1.0040874 | I312: =RANK(H312,H$307:H$456) -> 146 | K312: Atlanta - GA | L312: 1.0574214 | M312: =RANK(L312,L$307:L$456) -> 147 | O312: Atlanta - GA | P312: 1.1141259 | Q312: =RANK(P312,P$307:P$456) -> 145 | S312: Atlanta - GA | T312: 1.2627851 | U312: =RANK(T312,T$307:T$456) -> 119
A313: Augusta - GA | B313: =E161 -> 1.0157067 | C313: =M161 -> 1.0810644 | D313: =U161 -> 1.1449931 | E313: =AO161 -> 1.2950976 | G313: Augusta - GA | H313: 1.0157067 | I313: =RANK(H313,H$307:H$456) -> 88 | K313: Augusta - GA | L313: 1.0810644 | M313: =RANK(L313,L$307:L$456) -> 82 | O313: Augusta - GA | P313: 1.1449931 | Q313: =RANK(P313,P$307:P$456) -> 68 | S313: Augusta - GA | T313: 1.2950976 | U313: =RANK(T313,T$307:T$456) -> 65
A314: Austin - TX | B314: =E162 -> 1.0140774 | C314: =M162 -> 1.0932284 | D314: =U162 -> 1.159815 | E314: =AO162 -> 1.3269894 | G314: Austin - TX | H314: 1.0140774 | I314: =RANK(H314,H$307:H$456) -> 110 | K314: Austin - TX | L314: 1.0932284 | M314: =RANK(L314,L$307:L$456) -> 20 | O314: Austin - TX | P314: 1.159815 | Q314: =RANK(P314,P$307:P$456) -> 10 | S314: Austin - TX | T314: 1.3269894 | U314: =RANK(T314,T$307:T$456) -> 10
A315: Bakersfield - CA | B315: =E163 -> 1.0277535 | C315: =M163 -> 1.0962266 | D315: =U163 -> 1.1581277 | E315: =AO163 -> 1.3230948 | G315: Bakersfield - CA | H315: 1.0277535 | I315: =RANK(H315,H$307:H$456) -> 10 | K315: Bakersfield - CA | L315: 1.0962266 | M315: =RANK(L315,L$307:L$456) -> 9 | O315: Bakersfield - CA | P315: 1.1581277 | Q315: =RANK(P315,P$307:P$456) -> 11 | S315: Bakersfield - CA | T315: 1.3230948 | U315: =RANK(T315,T$307:T$456) -> 12
A316: Baltimore - MD | B316: =E164 -> 1.0185163 | C316: =M164 -> 1.0829222 | D316: =U164 -> 1.1470859 | E316: =AO164 -> 1.3000878 | G316: Baltimore - MD | H316: 1.0185163 | I316: =RANK(H316,H$307:H$456) -> 72 | K316: Baltimore - MD | L316: 1.0829222 | M316: =RANK(L316,L$307:L$456) -> 68 | O316: Baltimore - MD | P316: 1.1470859 | Q316: =RANK(P316,P$307:P$456) -> 60 | S316: Baltimore - MD | T316: 1.3000878 | U316: =RANK(T316,T$307:T$456) -> 53
...

Sheet Effective Rent-Forward
A1: Property Class Name | B1: Slice | C1: As Of | D1: Geography Name | E1: Concept Name | F1: 2025 Q2 EST | G1: 2025 Q3 | H1: 2025 Q4 | I1: 2026 Q1 | J1: 2026 Q2 | K1: 2026 Q3 | L1: 2026 Q4 | M1: 2027 Q1 | N1: 2027 Q2 | O1: 2027 Q3 | P1: 2027 Q4 | Q1: 2028 Q1 | R1: 2028 Q2 | S1: 2028 Q3 | T1: 2028 Q4 | U1: 2029 Q1 | V1: 2029 Q2 | W1: 2029 Q3 | X1: 2029 Q4 | Y1: 2030 Q1 | Z1: 2030 Q2 | AA1: 2030 Q3 | AB1: 2030 Q4 | AC1: 2031 Q1 | AD1: 2031 Q2 | AE1: 2031 Q3 | AF1: 2031 Q4 | AG1: 2032 Q1 | AH1: 2032 Q2 | AI1: 2032 Q3 | AJ1: 2032 Q4 | AK1: 2033 Q1 | AL1: 2033 Q2 | AM1: 2033 Q3 | AN1: 2033 Q4 | AO1: 2034 Q1 | AP1: 2034 Q2 | AQ1: 2034 Q3 | AR1: 2034 Q4 | AS1: 2035 Q1 | AT1: 2035 Q2
A2: Multi-Family | B2: All | C2: 2025 Q2 | D2: Akron - OH USA | E2: Market Effective Rent/Unit | F2: 1173.7147 | G2: 1175.7521 | H2: 1178.1387 | I2: 1195.8826 | J2: 1215.5674 | K2: 1215.7994 | L2: 1216.4722 | M2: 1232.7014 | N2: 1251.189 | O2: 1250.0874 | P2: 1249.5944 | Q2: 1265.0646 | R2: 1282.8558 | S2: 1280.4369 | T2: 1278.6558 | U2: 1293.4785 | V2: 1310.7584 | W2: 1307.5538 | X2: 1305.2738 | Y2: 1319.9353 | Z2: 1337.2505 | AA2: 1333.8212 | AB2: 1331.2163 | AC2: 1346.0217 | AD2: 1363.3959 | AE2: 1359.5105 | AF2: 1356.6105 | AG2: 1371.3103 | AH2: 1388.7587 | AI2: 1384.6039 | AJ2: 1381.3253 | AK2: 1396.1002 | AL2: 1413.6722 | AM2: 1409.2792 | AN2: 1405.7932 | AO2: 1420.6708 | AP2: 1438.3881 | AQ2: 1433.7904 | AR2: 1430.2635 | AS2: 1445.2723 | AT2: 1463.1763
A3: Multi-Family | B3: All | C3: 2025 Q2 | D3: Albany - NY USA | E3: Market Effective Rent/Unit | F3: 1637.1587 | G3: 1644.7206 | H3: 1652.5503 | I3: 1676.0369 | J3: 1700.7361 | K3: 1706.3 | L3: 1712.4794 | M3: 1734.1796 | N3: 1757.6462 | O3: 1762.1228 | P3: 1767.4073 | Q3: 1788.7728 | R3: 1811.6388 | S3: 1814.2527 | T3: 1817.7087 | U3: 1837.6295 | V3: 1859.2306 | W3: 1860.6909 | X3: 1863.3813 | Y3: 1883.3627 | Z3: 1905.2441 | AA3: 1906.592 | AB3: 1909.0769 | AC3: 1929.0104 | AD3: 1950.9277 | AE3: 1951.8318 | AF3: 1953.8241 | AG3: 1973.8303 | AH3: 1996.0789 | AI3: 1996.6399 | AJ3: 1998.5023 | AK3: 2018.8116 | AL3: 2041.1519 | AM3: 2041.5247 | AN3: 2043.2212 | AO3: 2063.5623 | AP3: 2086.1863 | AQ3: 2086.3721 | AR3: 2087.8992 | AS3: 2108.4663 | AT3: 2131.3623
A4: Multi-Family | B4: All | C4: 2025 Q2 | D4: Albuquerque - NM USA | E4: Market Effective Rent/Unit | F4: 1274.3367 | G4: 1280.0214 | H4: 1275.5364 | I4: 1292.4575 | J4: 1316.5404 | K4: 1321.3048 | L4: 1315.4692 | M4: 1331.1732 | N4: 1355.8215 | O4: 1360.9786 | P4: 1355.2192 | Q4: 1371.2806 | R4: 1396.0601 | S4: 1400.3665 | T4: 1393.2681 | U4: 1408.7716 | V4: 1433.3398 | W4: 1437.0151 | X4: 1429.3147 | Y4: 1444.9442 | Z4: 1470.0059 | AA4: 1473.797 | AB4: 1465.9238 | AC4: 1481.7516 | AD4: 1507.2478 | AE4: 1510.7655 | AF4: 1502.3267 | AG4: 1518.2542 | AH4: 1544.0743 | AI4: 1547.5707 | AJ4: 1538.8264 | AK4: 1555.0437 | AL4: 1581.3562 | AM4: 1584.7632 | AN4: 1575.5527 | AO4: 1592.0552 | AP4: 1618.9224 | AQ4: 1622.1736 | AR4: 1612.6018 | AS4: 1629.3447 | AT4: 1656.6873
A5: Multi-Family | B5: All | C5: 2025 Q2 | D5: Anchorage - AK USA | E5: Market Effective Rent/Unit | F5: 1439.4951 | G5: 1441.6759 | H5: 1439.3665 | I5: 1460.6713 | J5: 1490.9493 | K5: 1490.6996 | L5: 1485.8669 | M5: 1505.7767 | N5: 1535.7736 | O5: 1534.6224 | P5: 1528.907 | Q5: 1548.3129 | R5: 1577.7323 | S5: 1575.1467 | T5: 1568.0463 | U5: 1587.0032 | V5: 1616.4232 | W5: 1613.3197 | X5: 1605.7579 | Y5: 1625.0258 | Z5: 1655.1002 | AA5: 1651.9446 | AB5: 1644.2275 | AC5: 1663.9678 | AD5: 1694.7703 | AE5: 1691.228 | AF5: 1683.0266 | AG5: 1702.911 | AH5: 1734.0995 | AI5: 1730.5129 | AJ5: 1721.9832 | AK5: 1742.1777 | AL5: 1773.9264 | AM5: 1769.9402 | AN5: 1761.0786 | AO5: 1781.569 | AP5: 1813.8611 | AQ5: 1809.8215 | AR5: 1800.8022 | AS5: 1821.5966 | AT5: 1854.4487
A6: Multi-Family | B6: All | C6: 2025 Q2 | D6: Asheville - NC USA | E6: Market Effective Rent/Unit | F6: 1660.3861 | G6: 1664.3049 | H6: 1664.6427 | I6: 1682.3953 | J6: 1703.0485 | K6: 1707.4297 | L6: 1708.583 | M6: 1727.912 | N6: 1750.8865 | O6: 1758.0181 | P6: 1761.3689 | Q6: 1782.4778 | R6: 1806.4849 | S6: 1812.9347 | T6: 1815.0625 | U6: 1835.6035 | V6: 1859.1027 | W6: 1864.8826 | X6: 1866.4543 | Y6: 1886.9706 | Z6: 1910.8925 | AA6: 1916.4513 | AB6: 1917.4879 | AC6: 1937.9998 | AD6: 1961.8077 | AE6: 1966.7444 | AF6: 1967.3535 | AG6: 1987.9558 | AH6: 2011.932 | AI6: 2016.7307 | AJ6: 2016.7571 | AK6: 2037.4786 | AL6: 2061.8662 | AM6: 2066.3752 | AN6: 2066.1926 | AO6: 2087.0288 | AP6: 2111.6084 | AQ6: 2116.0259 | AR6: 2115.4226 | AS6: 2136.5659 | AT6: 2161.322
A7: Multi-Family | B7: All | C7: 2025 Q2 | D7: Atlanta - GA USA | E7: Market Effective Rent/Unit | F7: 1638.7471 | G7: 1636.5583 | H7: 1628.1398 | I7: 1645.3846 | J7: 1666.7172 | K7: 1664.9517 | L7: 1659.1624 | M7: 1681.9042 | N7: 1709.2465 | O7: 1712.2264 | P7: 1708.8317 | Q7: 1732.8328 | R7: 1760.0737 | S7: 1761.4041 | T7: 1756.239 | U7: 1779.5812 | V7: 1806.5394 | W7: 1807.3359 | X7: 1801.7682 | Y7: 1825.7988 | Z7: 1853.7145 | AA7: 1854.7457 | AB7: 1849.2252 | AC7: 1873.9116 | AD7: 1902.4048 | AE7: 1903.2806 | AF7: 1897.2439 | AG7: 1922.213 | AH7: 1951.0963 | AI7: 1951.6265 | AJ7: 1945.2578 | AK7: 1970.7189 | AL7: 2000.1825 | AM7: 2000.5538 | AN7: 1993.8539 | AO7: 2019.7845 | AP7: 2050.0166 | AQ7: 2050.1992 | AR7: 2043.13 | AS7: 2069.5215 | AT7: 2100.3308
A8: Multi-Family | B8: All | C8: 2025 Q2 | D8: Augusta - GA USA | E8: Market Effective Rent/Unit | F8: 1248.1744 | G8: 1250.2963 | H8: 1253.0529 | I8: 1267.7577 | J8: 1283.1492 | K8: 1285.9312 | L8: 1289.4059 | M8: 1305.3278 | N8: 1322.5818 | O8: 1327.2712 | P8: 1332.2461 | Q8: 1349.3489 | R8: 1366.8324 | S8: 1370.4038 | T8: 1374.0903 | U8: 1390.2771 | V8: 1407.0065 | W8: 1409.8217 | X8: 1412.9845 | Y8: 1429.1603 | Z8: 1446.115 | AA8: 1448.7574 | AB8: 1451.6165 | AC8: 1467.8278 | AD8: 1484.6758 | AE8: 1486.8083 | AF8: 1489.3145 | AG8: 1505.5209 | AH8: 1522.3741 | AI8: 1524.2041 | AJ8: 1526.2745 | AK8: 1542.5122 | AL8: 1559.5535 | AM8: 1561.1052 | AN8: 1563.0605 | AO8: 1579.4081 | AP8: 1596.6255 | AQ8: 1598.1284 | AR8: 1599.8966 | AS8: 1616.5652 | AT8: 1633.8965
A9: Multi-Family | B9: All | C9: 2025 Q2 | D9: Austin - TX USA | E9: Market Effective Rent/Unit | F9: 1559.1013 | G9: 1554.3123 | H9: 1552.9197 | I9: 1580.9395 | J9: 1611.1523 | K9: 1612.9994 | L9: 1613.3503 | M9: 1642.4783 | N9: 1675.0431 | O9: 1676.9661 | P9: 1676.0433 | Q9: 1704.3762 | R9: 1735.7134 | S9: 1734.9198 | T9: 1731.2522 | U9: 1758.1185 | V9: 1788.3074 | W9: 1786.0488 | X9: 1781.1829 | Y9: 1808.2256 | Z9: 1839.0729 | AA9: 1836.6434 | AB9: 1831.6746 | AC9: 1859.5479 | AD9: 1891.147 | AE9: 1888.4907 | AF9: 1883.0509 | AG9: 1911.1967 | AH9: 1943.3499 | AI9: 1940.2256 | AJ9: 1934.2424 | AK9: 1962.9775 | AL9: 1995.8257 | AM9: 1992.3927 | AN9: 1986.2338 | AO9: 2015.572 | AP9: 2049.1326 | AQ9: 2045.3807 | AR9: 2038.84 | AS9: 2068.9617 | AT9: 2103.2163
A10: Multi-Family | B10: All | C10: 2025 Q2 | D10: Bakersfield - CA USA | E10: Market Effective Rent/Unit | F10: 1388.4956 | G10: 1401.4734 | H10: 1411.6449 | I10: 1427.0361 | J10: 1442.156 | K10: 1453.0576 | L10: 1461.5021 | M10: 1475.5624 | N10: 1490.1024 | O10: 1500.5352 | P10: 1508.6293 | Q10: 1522.1439 | R10: 1535.8064 | S10: 1545.2391 | T10: 1552.2515 | U10: 1565.168 | V10: 1578.5339 | W10: 1587.8599 | X10: 1594.8779 | Y10: 1608.1267 | Z10: 1621.8671 | AA10: 1631.455 | AB10: 1638.6691 | AC10: 1652.2826 | AD10: 1666.4016 | AE10: 1676.0864 | AF10: 1683.3634 | AG10: 1697.2155 | AH10: 1711.5918 | AI10: 1721.582 | AJ10: 1728.8915 | AK10: 1742.9478 | AL10: 1757.543 | AM10: 1767.6301 | AN10: 1775.1415 | AO10: 1789.6168 | AP10: 1804.645 | AQ10: 1815.0402 | AR10: 1822.6982 | AS10: 1837.2802 | AT10: 1852.4121
A11: Multi-Family | B11: All | C11: 2025 Q2 | D11: Baltimore - MD USA | E11: Market Effective Rent/Unit | F11: 1732.5806 | G11: 1731.8152 | H11: 1733.2949 | I11: 1764.6938 | J11: 1794.6754 | K11: 1792.5269 | L11: 1792.1185 | M11: 1820.4266 | N11: 1849.4498 | O11: 1846.422 | P11: 1845.744 | Q11: 1876.3293 | R11: 1906.9677 | S11: 1903.6299 | T11: 1901.9637 | U11: 1932.3311 | V11: 1962.8871 | W11: 1958.6464 | X11: 1956.5243 | Y11: 1987.5551 | Z11: 2018.5878 | AA11: 2014.0287 | AB11: 2011.4501 | AC11: 2042.7531 | AD11: 2073.8179 | AE11: 2068.1018 | AF11: 2064.4397 | AG11: 2095.54 | AH11: 2126.573 | AI11: 2120.0857 | AJ11: 2115.9055 | AK11: 2147.3811 | AL11: 2178.9871 | AM11: 2172.1357 | AN11: 2167.6465 | AO11: 2199.8923 | AP11: 2232.051 | AQ11: 2224.8127 | AR11: 2219.991 | AS11: 2252.8091 | AT11: 2285.5181
A12: Multi-Family | B12: All | C12: 2025 Q2 | D12: Baton Rouge - LA USA | E12: Market Effective Rent/Unit | F12: 1187.1682 | G12: 1190.0919 | H12: 1189.3975 | I12: 1203.5527 | J12: 1219.4728 | K12: 1222.9315 | L12: 1222.8335 | M12: 1238.0226 | N12: 1255.6414 | O12: 1260.8363 | P12: 1262.0398 | Q12: 1278.2456 | R12: 1296.1536 | S12: 1300.4236 | T12: 1300.3643 | U12: 1315.7559 | V12: 1333.0592 | W12: 1336.6013 | X12: 1335.8906 | Y12: 1351.2002 | Z12: 1368.6697 | AA12: 1372.0522 | AB12: 1370.9321 | AC12: 1386.2656 | AD12: 1403.6387 | AE12: 1406.5406 | AF12: 1404.9498 | AG12: 1420.2413 | AH12: 1437.6422 | AI12: 1440.3467 | AJ12: 1438.3091 | AK12: 1453.7156 | AL12: 1471.4187 | AM12: 1473.9259 | AN12: 1471.6597 | AO12: 1487.1101 | AP12: 1504.876 | AQ12: 1507.233 | AR12: 1504.6096 | AS12: 1520.2644 | AT12: 1538.156
A13: Multi-Family | B13: All | C13: 2025 Q2 | D13: Beaumont - TX USA | E13: Market Effective Rent/Unit | F13: 1063.3517 | G13: 1067.0374 | H13: 1072.9893 | I13: 1086.6083 | J13: 1098.7694 | K13: 1101.5499 | L13: 1106.6677 | M13: 1119.2502 | N13: 1131.506 | O13: 1134.5319 | P13: 1139.949 | Q13: 1152.7524 | R13: 1164.8497 | S13: 1167.0386 | T13: 1171.6029 | U13: 1183.8331 | V13: 1195.4879 | W13: 1197.1134 | X13: 1201.4237 | Y13: 1213.7117 | Z13: 1225.478 | AA13: 1227.0723 | AB13: 1231.4193 | AC13: 1243.8208 | AD13: 1255.7389 | AE13: 1257.0968 | AF13: 1261.2858 | AG13: 1273.7574 | AH13: 1285.6772 | AI13: 1286.8959 | AJ13: 1291.0249 | AK13: 1303.5603 | AL13: 1315.5841 | AM13: 1316.6378 | AN13: 1320.6796 | AO13: 1333.5262 | AP13: 1345.8529 | AQ13: 1346.7573 | AR13: 1350.72 | AS13: 1363.6907 | AT13: 1376.0889
... A151: Multi-Family | B151: All | C151: 2025 Q2 | D151: Youngstown - OH USA | E151: Market Effective Rent/Unit | F151: 865.22693 | G151: 872.3147 | H151: 879.32184 | I151: 888.46008 | J151: 897.03534 | K151: 902.86639 | L151: 908.68982 | M151: 916.57385 | N151: 924.14111 | O151: 929.23322 | P151: 934.3985 | Q151: 941.60797 | R151: 948.46527 | S151: 952.67291 | T151: 956.94769 | U151: 963.54889 | V151: 969.90375 | W151: 973.73553 | X151: 977.76477 | Y151: 984.15161 | Z151: 990.37811 | AA151: 994.11157 | AB151: 998.01416 | AC151: 1004.4473 | AD151: 1010.5511 | AE151: 1013.9871 | AF151: 1017.6951 | AG151: 1023.872 | AH151: 1029.8793 | AI151: 1033.2922 | AJ151: 1036.8069 | AK151: 1042.9265 | AL151: 1048.8662 | AM151: 1052.1627 | AN151: 1055.627 | AO151: 1061.7667 | AP151: 1067.7218 | AQ151: 1070.9082 | AR151: 1074.3582 | AS151: 1080.426 | AT151: 1086.3
I153: 1 | Q153: 3 | Y153: 5 | AS153: 10
A154: Property Class Name | B154: Slice | C154: As Of | D154: Geography Name | E154: Concept Name | F154: =F1 -> 2025 Q2 EST | G154: =G1 -> 2025 Q3 | H154: =H1 -> 2025 Q4 | I154: =I1 -> 2026 Q1 | J154: =J1 -> 2026 Q2 | K154: =K1 -> 2026 Q3 | L154: =L1 -> 2026 Q4 | M154: =M1 -> 2027 Q1 | ... AS154: =AS1 -> 2035 Q1
A155: Multi-Family | B155: All | C155: 2024 Q3 | D155: Akron - OH USA | E155: Market Effective Rent/Unit | F155: =F2/$F2 -> 1 | G155: =G2/$F2 -> 1.0017358 | H155: =H2/$F2 -> 1.0037692 | I155: =I2/$F2 -> 1.0188869 | J155: =J2/$F2 -> 1.0356583 | K155: =K2/$F2 -> 1.035856 | L155: =L2/$F2 -> 1.0364292 | M155: =M2/$F2 -> 1.0502564 | ... AS155: =AS2/$F2 -> 1.2313659
A156: Multi-Family | B156: All | C156: 2024 Q3 | D156: Albany - NY USA | E156: Market Effective Rent/Unit | F156: =F3/$F3 -> 1 | G156: =G3/$F3 -> 1.0046189 | H156: =H3/$F3 -> 1.0094014 | I156: =I3/$F3 -> 1.0237473 | J156: =J3/$F3 -> 1.038834 | K156: =K3/$F3 -> 1.0422325 | L156: =L3/$F3 -> 1.046007 | M156: =M3/$F3 -> 1.0592617 | ... AS156: =AS3/$F3 -> 1.2878814
A157: Multi-Family | B157: All | C157: 2024 Q3 | D157: Albuquerque - NM USA | E157: Market Effective Rent/Unit | F157: =F4/$F4 -> 1 | G157: =G4/$F4 -> 1.0044609 | H157: =H4/$F4 -> 1.0009414 | I157: =I4/$F4 -> 1.0142198 | J157: =J4/$F4 -> 1.0331182 | K157: =K4/$F4 -> 1.0368569 | L157: =L4/$F4 -> 1.0322776 | M157: =M4/$F4 -> 1.0446009 | ... AS157: =AS4/$F4 -> 1.2785826
A158: Multi-Family | B158: All | C158: 2024 Q3 | D158: Anchorage - AK USA | E158: Market Effective Rent/Unit | F158: =F5/$F5 -> 1 | G158: =G5/$F5 -> 1.001515 | H158: =H5/$F5 -> 0.99991062 | I158: =I5/$F5 -> 1.0147108 | J158: =J5/$F5 -> 1.0357446 | K158: =K5/$F5 -> 1.0355711 | L158: =L5/$F5 -> 1.032214 | M158: =M5/$F5 -> 1.046045 | ... AS158: =AS5/$F5 -> 1.2654413
A159: Multi-Family | B159: All | C159: 2024 Q3 | D159: Asheville - NC USA | E159: Market Effective Rent/Unit | F159: =F6/$F6 -> 1 | G159: =G6/$F6 -> 1.0023602 | H159: =H6/$F6 -> 1.0025636 | I159: =I6/$F6 -> 1.0132554 | J159: =J6/$F6 -> 1.0256942 | K159: =K6/$F6 -> 1.0283329 | L159: =L6/$F6 -> 1.0290275 | M159: =M6/$F6 -> 1.0406688 | ... AS159: =AS6/$F6 -> 1.2867886
A160: Multi-Family | B160: All | C160: 2024 Q3 | D160: Atlanta - GA USA | E160: Market Effective Rent/Unit | F160: =F7/$F7 -> 1 | G160: =G7/$F7 -> 0.99866439 | H160: =H7/$F7 -> 0.99352719 | I160: =I7/$F7 -> 1.0040504 | J160: =J7/$F7 -> 1.017068 | K160: =K7/$F7 -> 1.0159906 | L160: =L7/$F7 -> 1.0124579 | M160: =M7/$F7 -> 1.0263354 | ... AS160: =AS7/$F7 -> 1.2628682
A161: Multi-Family | B161: All | C161: 2024 Q3 | D161: Augusta - GA USA | E161: Market Effective Rent/Unit | F161: =F8/$F8 -> 1 | G161: =G8/$F8 -> 1.0016999 | H161: =H8/$F8 -> 1.0039084 | I161: =I8/$F8 -> 1.0156895 | J161: =J8/$F8 -> 1.0280207 | K161: =K8/$F8 -> 1.0302495 | L161: =L8/$F8 -> 1.0330334 | M161: =M8/$F8 -> 1.0457895 | ... AS161: =AS8/$F8 -> 1.2951436
A162: Multi-Family | B162: All | C162: 2024 Q3 | D162: Austin - TX USA | E162: Market Effective Rent/Unit | F162: =F9/$F9 -> 1 | G162: =G9/$F9 -> 0.99692832 | H162: =H9/$F9 -> 0.99603513 | I162: =I9/$F9 -> 1.0140069 | J162: =J9/$F9 -> 1.0333853 | K162: =K9/$F9 -> 1.03457 | L162: =L9/$F9 -> 1.0347951 | M162: =M9/$F9 -> 1.0534776 | ... AS162: =AS9/$F9 -> 1.3270219
A163: Multi-Family | B163: All | C163: 2024 Q3 | D163: Bakersfield - CA USA | E163: Market Effective Rent/Unit | F163: =F10/$F10 -> 1 | G163: =G10/$F10 -> 1.0093467 | H163: =H10/$F10 -> 1.0166722 | I163: =I10/$F10 -> 1.027757 | J163: =J10/$F10 -> 1.0386464 | K163: =K10/$F10 -> 1.0464978 | L163: =L10/$F10 -> 1.0525795 | M163: =M10/$F10 -> 1.0627058 | ... AS163: =AS10/$F10 -> 1.3232164
A164: Multi-Family | B164: All | C164: 2024 Q3 | D164: Baltimore - MD USA | E164: Market Effective Rent/Unit | F164: =F11/$F11 -> 1 | G164: =G11/$F11 -> 0.99955824 | H164: =H11/$F11 -> 1.0004123 | I164: =I11/$F11 -> 1.0185349 | J164: =J11/$F11 -> 1.0358395 | K164: =K11/$F11 -> 1.0345994 | L164: =L11/$F11 -> 1.0343637 | M164: =M11/$F11 -> 1.0507024 | ... AS164: =AS11/$F11 -> 1.3002622
A165: Multi-Family | B165: All | C165: 2024 Q3 | D165: Baton Rouge - LA USA | E165: Market Effective Rent/Unit | F165: =F12/$F12 -> 1 | G165: =G12/$F12 -> 1.0024628 | H165: =H12/$F12 -> 1.0018778 | I165: =I12/$F12 -> 1.0138013 | J165: =J12/$F12 -> 1.0272114 | K165: =K12/$F12 -> 1.0301249 | L165: =L12/$F12 -> 1.0300423 | M165: =M12/$F12 -> 1.0428367 | ... AS165: =AS12/$F12 -> 1.2805805
A166: Multi-Family | B166: All | C166: 2024 Q3 | D166: Beaumont - TX USA | E166: Market Effective Rent/Unit | F166: =F13/$F13 -> 1 | G166: =G13/$F13 -> 1.0034661 | H166: =H13/$F13 -> 1.0090634 | I166: =I13/$F13 -> 1.021871 | J166: =J13/$F13 -> 1.0333076 | K166: =K13/$F13 -> 1.0359225 | L166: =L13/$F13 -> 1.0407354 | M166: =M13/$F13 -> 1.0525683 | ... AS166: =AS13/$F13 -> 1.2824456
... A304: Multi-Family | B304: All | C304: 2024 Q3 | D304: Youngstown - OH USA | E304: Market Effective Rent/Unit | F304: =F151/$F151 -> 1 | G304: =G151/$F151 -> 1.0081918 | H304: =H151/$F151 -> 1.0162904 | I304: =I151/$F151 -> 1.0268521 | J304: =J151/$F151 -> 1.0367631 | K304: =K151/$F151 -> 1.0435024 | L304: =L151/$F151 -> 1.0502329 | M304: =M151/$F151 -> 1.059345 | ... AS304: =AS151/$F151 -> 1.2487198
B306: 1 | C306: 3 | D306: 5 | E306: 10 | G306: Market | H306: Index | I306: 1 | L306: Market | M306: Index | N306: 3 | P306: Market | Q306: Index | R306: 5 | T306: Market | U306: Index | V306: 10
A307: =D155 -> Akron - OH USA | B307: =I155 -> 1.0188869 | C307: =Q155 -> 1.0778297 | D307: =Y155 -> 1.1245793 | E307: =AS155 -> 1.2313659 | G307: Akron - OH USA | H307: 1.0188869 | I307: =RANK(H307,H$307:H$456) -> 69 | L307: Akron - OH USA | M307: 1.0778297 | N307: =RANK(M307,M$307:M$456) -> 104 | P307: Akron - OH USA | Q307: 1.1245793 | R307: =RANK(Q307,Q$307:Q$456) -> 133 | T307: Akron - OH USA | U307: 1.2313659 | V307: =RANK(U307,U$307:U$456) -> 145
